Workbook
Name CARTONAL: Tabla3[CARTONAL]
Name CELOVEN: INTERNACIONAL_PAPER[CELOVEN]
Name CLIENTE: #REF!
Name EUROPACIFIC: Tabla5[EUROPACIFIC]
Name FLEXAM: INTERNACIONAL_PAPER[FLEXAM]
Name INTERNACIONAL_PAPEL: #REF!
Name MCLTLP: INTERNACIONAL_PAPER[MCLTLP]
Name MORROCEL: INTERNACIONAL_PAPER[MORROCEL]
Name OPPFILM: INTERNACIONAL_PAPER[OPPFILM]
Name PLASTICOS.DE.EMPAQUE: INTERNACIONAL_PAPER[PLASTICOS.DE.EMPAQUE]
Name plasticos.del.litoral: INTERNACIONAL_PAPER[plasticos.del.litoral]
Name PRODUCTO: #REF!
Name PRODUCTO: #REF!
Name PRODUCTO: #REF!
Name PRODUCTOS: #REF!
Name PRODUCTOS: #REF!
Name PRODUCTOS: #REF!
Name PRODUCTOS.: #REF!
Name Proveedor: Tabla1[Proveedor]
Name QUIMATIC.SPA.IMP: INTERNACIONAL_PAPER[QUIMATIC.SPA.IMP]
Name RETANA: INTERNACIONAL_PAPER[RETANA]
Name TECHNOFILM: INTERNACIONAL_PAPER[[#All],[TECHNOFILM]]
Name TELEPLASTIC: INTERNACIONAL_PAPER[TELEPLASTIC]
Name trabajo: Tabla2[lista]

Sheet OEE
B2: =D6 -> 0.58156597 | C2: =E6 -> 0.82564126 | D2: =F6 -> 0.91040658
B3: Eficiencia General de los Equipos
B4: (OEE - Overall Equipment Effectiveness)
B5: CUREX | C5: O.E.E | D5: Disponibilidad | E5: Rendimiento | F5: Calidad
C6: =B2*C2*D2 -> 0.43714525 | D6: =((OLYMPIA!AF28-OLYMPIA!AC28-OLYMPIA!Q28)+(NOVOFLEX.!AF72-NOVOFLEX.!AC72-NOVOFLEX.!Q72))/(OLYMPIA!D8+NOVOFLEX.!D7) -> 0.58156597 | E6: =(NOVOFLEX.!BV72+OLYMPIA!BV28)/(75+68) -> 0.82564126 | F6: =100%-(NOVOFLEX.!CA72+OLYMPIA!CA28)/(NOVOFLEX.!BO72+OLYMPIA!BO28) -> 0.91040658
C10: O.E.E | D10: Disponibilidad | E10: Rendimiento | F10: Calidad
B11: Novoflex | C11: =NOVOFLEX.!I5 -> 0.72536539 | D11: =NOVOFLEX.!D5 -> 0.92923611 | E11: =NOVOFLEX.!E5 -> 0.8596378 | F11: =NOVOFLEX.!F5 -> 0.90806147
B12: Olympia | C12: =OLYMPIA!I7 -> 0.16949709 | D12: =OLYMPIA!D7 -> 0.23389583 | E12: =OLYMPIA!E7 -> 0.78814509 | F12: =OLYMPIA!F7 -> 0.91946156

Sheet OLYMPIA
A5: INFORME MENSUAL DE PRODUCCION | CJ5: 72m/m | CK5: 0.12
A6: OLYMPIA | D6: Disponibilidad | E6: Rendimiento | F6: Calidad | I6: OEE OLYMPIA | N6: =D7 -> 0.23389583 | O6: =E7 -> 0.78814509 | P6: =F7 -> 0.91946156
A7: MES: | B7: MARZO | D7: =(AF28-AC28-Q28)/D8 -> 0.23389583 | E7: =((BK28/(AF28-AC28-Q28-W28))/68) -> 0.78814509 | F7: =100%-CB28 -> 0.91946156 | I7: =(N6*O6*P6) -> 0.16949709
A8: DIAS TRABAJADOS : | C8: 20 | D8: =C8*24*60 -> 28800 | E8: =C8*24 -> 480
A9: PEDIDO | B9: CODIGO DE MAQUINA | C9: FECHA | D9: CODIGO PRODUCTO | E9: O/P | F9: DESTINO | G9: N° DE TRABAJOS | H9: COMPAÑÍA | I9: NOMBRE DEL CLIENTE | J9: PRODUCTO | K9: CLIENTE Kg | L9: TIEMPO DE PARADAS EN MINUTOS | AD9: TOTAL TIEMPO PARADAS min. | AE9: TIEMPO EFECTIVO PRODUCCION min. | AF9: TOTAL TIEMPO PRODUCCION min. | AG9: DIAS TRABAJADOS | AH9: EFICIENCIA DE MAQUINA | AI9: ENTRADA DE MATERIA PRIMA | AZ9: SALIDA DE MATERIALES | BR9: DATOS DE TINTA Kg. | BU9: VELOCIDAD m/min. | BW9: DESPERDICIO | CE9: OBSERVACIONES
L10: PREPARACION | M10: PRE-PRENSA | N10: COLORIMETRIA | O10: CALIDAD | P10: MANTENIMIENTO | Q10: Limpieza general de Maquina | R10: PLANIFICACION | S10: LIMPIEZA DE PLANCHA | T10: LIMPIEZA DE RODILLO | U10: LIMPIEZA DE TAMBOR CENTRAL | V10: PRODUCCION | W10: PRUEBAS | X10: LOGISTICA | Y10: FALLAS ELECT | Z10: APROBACIONES | AA10: ESTANDAR DE COLOR | AB10: RRHH | AC10: FALTA DE INSUMO /PEDIDO
AI11: PELICULAS | AN11: TINTAS Kg | AW11: CONSUMO | AX11: SOLVENTE Lts | AZ11: PELICULA DEVOLUCION | BC11: TINTAS KG EN DEVOLUCION | BK11: PRODUCTO TERMINADO | BP11: SOLVENTE Lts | BR11: CONSUMO DE TINTA BLANCO | BS11: CONSUMO DE TINTA VARIAS | BT11: CONSUMO TOTAL | BU11: VELOCIDAD DE MAQUINA TEORICA ML/min. | BV11: VELOCIDAD DE MAQUINA REAL ML/min. | BW11: m/l | BY11: m2 | CA11: Kg
AI12: m/l | AJ12: GRAMAJE g/m2 | AK12: ANCHO mm | AL12: m2 | AM12: Kg | AN12: # COLORES | AO12: BLANCO | AP12: AZUL REFLEX | AQ12: MAGENTA | AR12: AMARILLO | AS12: CYAN | AT12: ROJO | AU12: OTRAS | AV12: TOTAL | AX12: PRODUCCION | AY12: LIMPIEZA | AZ12: m/l | BA12: m2 | BB12: Kg | BC12: BLANCO | BD12: AZUL REFLEX | BE12: MAGENTA | BF12: AMARILLO | BG12: CYAN | BH12: ROJO | BI12: OTRAS | BJ12: TOTAL | BK12: m/l | BL12: GRAMAJE g/m2 | BM12: ANCHO mm | BN12: m2 | BO12: Kg | BP12: PRODUCCION | BQ12: LIMPIEZA
BW13: CANT | BX13: % | BY13: CANT | BZ13: % | CA13: CANT | CB13: % | CC13: MAT. OBSERVACION | CD13: MAT. RECHAZADO | CF13: Tipo de Trabajo | CG13: nº de pantone | CH13: Aplic Tinta Humeda | CI13: M/L Estandar de Dsp | CJ13: Metros de Dsp | CK13: Cumplimiento Estandar | CL13: fecha de entrega | CM13: cumplimiento entrega | CN13: metros op | CO13: Cumplimiento Fabricado | CP13: material reciclado | CQ13: Proveedor | CR13: Material
AF14: +
A15: 21-0575 | B15: OF | C15: 46118 | D15: =IFERROR(VLOOKUP($A15,Hoja3!$A$3:$F$6000,2,FALSE),"") -> TXSPSP035B002 | E15: 16619 | F15: =IFERROR(VLOOKUP($A15,Hoja3!$A$3:$F$6000,6,FALSE),"") -> LAMINACION | G15: 1 | H15: =IFERROR(VLOOKUP($A15,Hoja3!$A$3:$F$6000,5,FALSE),"") -> CX | I15: =IFERROR(VLOOKUP($A15,Hoja3!$A$3:$F$6000,3,FALSE),"") -> C.A. SUCESORA DE JOSE PUIG & CIA | J15: =IFERROR(VLOOKUP($A15,Hoja3!$A$3:$F$6000,4,FALSE),"") -> ENVOLTORIO EXTERNO IMPRESO SODA PUIG 240g | K15: 5000 | L15: =90+40+60+40 -> 230 | M15: =20+40+60+240+40 -> 400 | N15: =120+35+35+20+45 -> 255 | O15: 30 | P15: =30+30+60 -> 120 | Q15: 0 | R15: 0 | S15: =15+15+15+15+15+20+15 -> 110 | T15: 10 | U15: 10 | V15: =20+30+15+20+60+30 -> 175 | W15: 0 | X15: =30+40 -> 70 | Y15: 0 | Z15: 0 | AA15: 0 | AB15: =30+60+30+30+60 -> 210 | AC15: 0 | AD15: =SUM(L15:AC15) -> 1620 | AE15: 1350 | AF15: =SUM(AD15:AE15) -> 2970 | AG15: =AF15/(60*24) -> 2.0625 | AH15: =IFERROR(AE15/AF15,0) -> 0.45454545 | AI15: =124530+84300 -> 208830 | AJ15: 14 | AK15: 1090 | AL15: =IF(AM15=0,0,(+AI15*AK15/1000)) -> 227624.7 | AM15: =1276+1878 -> 3154 | AN15: 5 | AO15: 560 | AP15: 73 | AQ15: 40 | AR15: 40 | AS15: 0 | AT15: 0 | AU15: 33 | AV15: =SUM(AO15:AU15) -> 746 | AW15: =+(AM15+(BR15*50/100))+(BS15*30/100)-BB15 -> 3403.9 | AX15: 0 | AY15: 0 | AZ15: 0 | BA15: 0 | BB15: 0 | BC15: 140 | BD15: 12 | BE15: 11 | BF15: 13 | BG15: 0 | BH15: 0 | BI15: 17 | BJ15: =SUM(BC15:BI15) -> 193 | BK15: =(72280+117730)-10914 -> 179096 | BL15: =IFERROR(+BO15*1000/((BK15)*(BM15/1000)),0) -> 14.749918 | BM15: =AK15 -> 1090 | BN15: =+BK15*BM15/1000 -> 195214.64 | BO15: =(1153+1901)-174.6 -> 2879.4 | BP15: 0 | BQ15: 0 | BR15: =AO15-BC15 -> 420 | BS15: =(AP15+AQ15+AR15+AS15+AT15+AU15)-(BD15+BE15+BF15+BG15+BH15+BI15) -> 133 | BT15: =BR15+BS15 -> 553 | BU15: =IFERROR(+BK15/AE15,0) -> 132.6637 | BV15: =IFERROR(+BK15/(AF15),0) -> 60.301684 | BW15: =IFERROR(+(AI15-AZ15)-BK15,0) -> 29734 | BX15: =IFERROR(+BW15/BK15,0) -> 0.16602269 | BY15: =IFERROR(+(AL15-BA15)-BN15,0) -> 32410.06 | BZ15: =IFERROR(+BY15/BN15,0) -> 0.16602269 | CA15: =IFERROR(+AW15-(BO15),0) -> 524.5 | CB15: =IFERROR(+CA15/BO15,1) -> 0.182156 | CC15: 0 | CD15: 0 | CE15: apariencia defectuosa en tramas por exceso decrecorrido en planchas, porosidad color azul, sucio color magenta en un solo ejemplar | CF15: REPETICION | CG15: 0 | CH15: =IFERROR((BT15*1000)/BN15,"") -> 2.8327793 | CI15: 3500 | CJ15: =IF(BW15=0,"",CI15-BW15) -> -26234 | CK15: {=_xlfn.IFS(CJ15>0,"CUMPLE",CJ15<0,"NO CUMPLE",CJ15="","")} -> NO CUMPLE | CL15: 46125 | CM15: {=_xlfn.IFS(CL15-C15 > 0,"CUMPLE",CL15-C15 < 0,"NO CUMPLE")} -> CUMPLE | CN15: 190000 | CO15: =BK15-CN15 -> -10904 | CP15: 900 | CQ15: OPPFILM | CR15: BOPP SC TRANSPARENTE
A16: 01-6075 | B16: OF | C16: 46125 | D16: =IFERROR(VLOOKUP($A16,Hoja3!$A$3:$F$6000,2,FALSE),"") -> TMMCGP228A000 | E16: 16620 | F16: =IFERROR(VLOOKUP($A16,Hoja3!$A$3:$F$6000,6,FALSE),"") -> LAMINACION | G16: 1 | H16: =IFERROR(VLOOKUP($A16,Hoja3!$A$3:$F$6000,5,FALSE),"") -> MCL | I16: =IFERROR(VLOOKUP($A16,Hoja3!$A$3:$F$6000,3,FALSE),"") -> MORROCEL, C.A. | J16: =IFERROR(VLOOKUP($A16,Hoja3!$A$3:$F$6000,4,FALSE),"") -> LINNER MTP IMPRESO GARANTIA DE PUREZA | K16: 5000 | L16: 70 | M16: 0 | N16: 20 | O16: 0 | P16: 0 | Q16: 0 | R16: 0 | S16: 0 | T16: 0 | U16: 0 | V16: =70+70 -> 140 | W16: 0 | X16: 25 | Y16: 0 | Z16: 0 | AA16: 0 | AB16: 0 | AC16: 0 | AD16: =SUM(L16:AC16) -> 255 | AE16: 225 | AF16: =SUM(AD16:AE16) -> 480 | AG16: =AF16/(60*24) -> 0.33333333 | AH16: =IFERROR(AE16/AF16,0) -> 0.46875 | AI16: 18076 | AJ16: 168 | AK16: 965 | AL16: =IF(AM16=0,0,(+AI16*AK16/1000)) -> 17443.34 | AM16: 4079.6 | AN16: 1 | AO16: 0 | AP16: 0 | AQ16: 0 | AR16: 0 | AS16: 0 | AT16: 28 | AU16: 0 | AV16: =SUM(AO16:AU16) -> 28 | AW16: =+(AM16+(BR16*50/100))+(BS16*30/100)-BB16 -> 4082.3 | AX16: 0 | AY16: 0 | AZ16: 0 | BA16: 0 | BB16: 0 | BC16: 0 | BD16: 0 | BE16: 0 | BF16: 0 | BG16: 0 | BH16: 19 | BI16: 0 | BJ16: =SUM(BC16:BI16) -> 19 | BK16: 17897 | BL16: =IFERROR(+BO16*1000/((BK16)*(BM16/1000)),0) -> 232.12273 | BM16: =AK16 -> 965 | BN16: =+BK16*BM16/1000 -> 17270.605 | BO16: 4008.9 | BP16: 0 | BQ16: 0 | BR16: =AO16-BC16 -> 0 | BS16: =(AP16+AQ16+AR16+AS16+AT16+AU16)-(BD16+BE16+BF16+BG16+BH16+BI16) -> 9 | BT16: =BR16+BS16 -> 9 | BU16: =IFERROR(+BK16/AE16,0) -> 79.542222 | BV16: =IFERROR(+BK16/(AF16),0) -> 37.285417 | BW16: =IFERROR(+(AI16-AZ16)-BK16,0) -> 179 | BX16: =IFERROR(+BW16/BK16,0) -> 0.010001676 | BY16: =IFERROR(+(AL16-BA16)-BN16,0) -> 172.735 | BZ16: =IFERROR(+BY16/BN16,0) -> 0.010001676 | CA16: =IFERROR(+AW16-(BO16),0) -> 73.4 | CB16: =IFERROR(+CA16/BO16,1) -> 0.018309262 | CC16: 0 | CD16: 0 | CE16: se culmina sin novedad | CF16: REPETICION | CG16: 0 | CH16: =IFERROR((BT16*1000)/BN16,"") -> 0.52111666 | CI16: 3500 | CJ16: =IF(BW16=0,"",CI16-BW16) -> 3321 | CK16: {=_xlfn.IFS(CJ16>0,"CUMPLE",CJ16<0,"NO CUMPLE",CJ16="","")} -> CUMPLE | CL16: 46132 | CM16: {=_xlfn.IFS(CL16-C16 > 0,"CUMPLE",CL16-C16 < 0,"NO CUMPLE")} -> CUMPLE | CN16: 22000 | CO16: =BK16-CN16 -> -4103 | CP16: 0 | CQ16: MORROCEL | CR16: LINNER MTP GARANTIA DE PUREZA
A17: 01-6019 | B17: OP | C17: 46126 | D17: =IFERROR(VLOOKUP($A17,Hoja3!$A$3:$F$6000,2,FALSE),"") -> TMARMZ044B001 | E17: 16557. | F17: =IFERROR(VLOOKUP($A17,Hoja3!$A$3:$F$6000,6,FALSE),"") -> LAMINACION | G17: 1 | H17: =IFERROR(VLOOKUP($A17,Hoja3!$A$3:$F$6000,5,FALSE),"") -> MCL | I17: =IFERROR(VLOOKUP($A17,Hoja3!$A$3:$F$6000,3,FALSE),"") -> ALFONZO RIVAS & CIA, C.A. | J17: =IFERROR(VLOOKUP($A17,Hoja3!$A$3:$F$6000,4,FALSE),"") -> LAMINACION IMPRESA MAIZINA 400g | K17: 0 | L17: 60 | M17: 0 | N17: 0 | O17: 15 | P17: 25 | Q17: 0 | R17: 0 | S17: 10 | T17: 0 | U17: 5 | V17: 0 | W17: 0 | X17: =45+50 -> 95 | Y17: 0 | Z17: 0 | AA17: 0 | AB17: 0 | AC17: 0 | AD17: =SUM(L17:AC17) -> 210 | AE17: 184.8 | AF17: =SUM(AD17:AE17) -> 394.8 | AG17: =AF17/(60*24) -> 0.27416667 | AH17: =IFERROR(AE17/AF17,0) -> 0.46808511 | AI17: 27624 | AJ17: 44 | AK17: 940 | AL17: =IF(AM17=0,0,(+AI17*AK17/1000)) -> 25966.56 | AM17: 1128.2 | AN17: 1 | AO17: 0 | AP17: 0 | AQ17: 0 | AR17: 0 | AS17: 0 | AT17: 0 | AU17: 140 | AV17: =SUM(AO17:AU17) -> 140 | AW17: =+(AM17+(BR17*50/100))+(BS17*30/100)-BB17 -> 1137.8 | AX17: 0 | AY17: 0 | AZ17: 0 | BA17: 0 | BB17: 0 | BC17: 0 | BD17: 0 | BE17: 0 | BF17: 0 | BG17: 0 | BH17: 0 | BI17: 108 | BJ17: =SUM(BC17:BI17) -> 108 | BK17: 26749 | BL17: =IFERROR(+BO17*1000/((BK17)*(BM17/1000)),0) -> 43.863242 | BM17: =AK17 -> 940 | BN17: =+BK17*BM17/1000 -> 25144.06 | BO17: 1102.9 | BP17: 0 | BQ17: 0 | BR17: =AO17-BC17 -> 0 | BS17: =(AP17+AQ17+AR17+AS17+AT17+AU17)-(BD17+BE17+BF17+BG17+BH17+BI17) -> 32 | BT17: =BR17+BS17 -> 32 | BU17: =IFERROR(+BK17/AE17,0) -> 144.74567 | BV17: =IFERROR(+BK17/(AF17),0) -> 67.753293 | BW17: =IFERROR(+(AI17-AZ17)-BK17,0) -> 875 | BX17: =IFERROR(+BW17/BK17,0) -> 0.032711503 | BY17: =IFERROR(+(AL17-BA17)-BN17,0) -> 822.5 | BZ17: =IFERROR(+BY17/BN17,0) -> 0.032711503 | CA17: =IFERROR(+AW17-(BO17),0) -> 34.9 | CB17: =IFERROR(+CA17/BO17,1) -> 0.031643848 | CC17: 0 | CD17: 0 | CE17: aplicación de compuesto deslizante | CF17: REPETICION | CG17: 0 | CH17: =IFERROR((BT17*1000)/BN17,"") -> 1.2726664 | CI17: 3500 | CJ17: =IF(BW17=0,"",CI17-BW17) -> 2625 | CK17: {=_xlfn.IFS(CJ17>0,"CUMPLE",CJ17<0,"NO CUMPLE",CJ17="","")} -> CUMPLE | CL17: 46132 | CM17: {=_xlfn.IFS(CL17-C17 > 0,"CUMPLE",CL17-C17 < 0,"NO CUMPLE")} -> CUMPLE | CN17: 28000 | CO17: =BK17-CN17 -> -1251 | CP17: 0 | CQ17: TELEPLASTIC | CR17: BOPP OCTS TRANSPARENTE
A18: 01-6078 | B18: OF | C18: 46127 | D18: =IFERROR(VLOOKUP($A18,Hoja3!$A$3:$F$6000,2,FALSE),"") -> TMCCTM1270001 | E18: 16621 | F18: =IFERROR(VLOOKUP($A18,Hoja3!$A$3:$F$6000,6,FALSE),"") -> LAMINACION | G18: 1 | H18: =IFERROR(VLOOKUP($A18,Hoja3!$A$3:$F$6000,5,FALSE),"") -> MCL | I18: =IFERROR(VLOOKUP($A18,Hoja3!$A$3:$F$6000,3,FALSE),"") -> PRODUCTOS ALIMENTOS COOK CHILL, C.A. | J18: =IFERROR(VLOOKUP($A18,Hoja3!$A$3:$F$6000,4,FALSE),"") -> LAMINACION TAPAS MINITINA SIN IMPRESIÓN | K18: 450 | L18: 40 | M18: 0 | N18: 0 | O18: 25 | P18: 0 | Q18: 0 | R18: 0 | S18: 0 | T18: 0 | U18: 0 | V18: 0 | W18: 0 | X18: 0 | Y18: 0 | Z18: 0 | AA18: 0 | AB18: 0 | AC18: 0 | AD18: =SUM(L18:AC18) -> 65 | AE18: 40.2 | AF18: =SUM(AD18:AE18) -> 105.2 | AG18: =AF18/(60*24) -> 0.073055556 | AH18: =IFERROR(AE18/AF18,0) -> 0.38212928 | AI18: 4090 | AJ18: 126 | AK18: 900 | AL18: =IF(AM18=0,0,(+AI18*AK18/1000)) -> 3681 | AM18: 454 | AN18: 1 | AO18: 0 | AP18: 0 | AQ18: 0 | AR18: 0 | AS18: 0 | AT18: 0 | AU18: 30 | AV18: =SUM(AO18:AU18) -> 30 | AW18: =+(AM18+(BR18*50/100))+(BS18*30/100)-BB18 -> 456.1 | AX18: 0 | AY18: 0 | AZ18: 0 | BA18: 0 | BB18: 0 | BC18: 0 | BD18: 0 | BE18: 0 | BF18: 0 | BG18: 0 | BH18: 0 | BI18: 23 | BJ18: =SUM(BC18:BI18) -> 23 | BK18: 3950 | BL18: =IFERROR(+BO18*1000/((BK18)*(BM18/1000)),0) -> 123.0661 | BM18: =AK18 -> 900 | BN18: =+BK18*BM18/1000 -> 3555 | BO18: 437.5 | BP18: 0 | BQ18: 0 | BR18: =AO18-BC18 -> 0 | BS18: =(AP18+AQ18+AR18+AS18+AT18+AU18)-(BD18+BE18+BF18+BG18+BH18+BI18) -> 7 | BT18: =BR18+BS18 -> 7 | BU18: =IFERROR(+BK18/AE18,0) -> 98.258706 | BV18: =IFERROR(+BK18/(AF18),0) -> 37.547529 | BW18: =IFERROR(+(AI18-AZ18)-BK18,0) -> 140 | BX18: =IFERROR(+BW18/BK18,0) -> 0.035443038 | BY18: =IFERROR(+(AL18-BA18)-BN18,0) -> 126 | BZ18: =IFERROR(+BY18/BN18,0) -> 0.035443038 | CA18: =IFERROR(+AW18-(BO18),0) -> 18.6 | CB18: =IFERROR(+CA18/BO18,1) -> 0.042514286 | CC18: 0 | CD18: 0 | CE18: durante la corrida se puede apreciar arrugas intermitente de bobina madre | CF18: REPETICION | CG18: 0 | CH18: =IFERROR((BT18*1000)/BN18,"") -> 1.9690577 | CI18: 3500 | CJ18: =IF(BW18=0,"",CI18-BW18) -> 3360 | CK18: {=_xlfn.IFS(CJ18>0,"CUMPLE",CJ18<0,"NO CUMPLE",CJ18="","")} -> CUMPLE | CL18: 46139 | CM18: {=_xlfn.IFS(CL18-C18 > 0,"CUMPLE",CL18-C18 < 0,"NO CUMPLE")} -> CUMPLE | CN18: 3000 | CO18: =BK18-CN18 -> 950 | CP18: 350 | CQ18: MORROCEL | CR18: LAMINACION TAPA MINITINA SIN IMPRESIÓN
A19: 01-6040 | B19: OF | C19: 46133 | D19: =IFERROR(VLOOKUP($A19,Hoja3!$A$3:$F$6000,2,FALSE),"") -> TXPCGP023B001 | E19: 16578 | F19: =IFERROR(VLOOKUP($A19,Hoja3!$A$3:$F$6000,6,FALSE),"") -> CORTE | G19: 1 | H19: =IFERROR(VLOOKUP($A19,Hoja3!$A$3:$F$6000,5,FALSE),"") -> CX | I19: =IFERROR(VLOOKUP($A19,Hoja3!$A$3:$F$6000,3,FALSE),"") -> PEPSI-COLA VENEZUELA, C.A. | J19: =IFERROR(VLOOKUP($A19,Hoja3!$A$3:$F$6000,4,FALSE),"") -> ETIQUETA IMPRESA GOLDEN PIÑA 1,5L | K19: 740 | L19: 30 | M19: 115 | N19: =15+20+20+10 -> 65 | O19: 15 | P19: 70 | Q19: 0 | R19: 0 | S19: =50+20+15+15+10+20 -> 130 | T19: 45 | U19: 0 | V19: =20+20+30 -> 70 | W19: 0 | X19: 40 | Y19: 0 | Z19: 0 | AA19: 0 | AB19: 80 | AC19: 0 | AD19: =SUM(L19:AC19) -> 660 | AE19: 385.2 | AF19: =SUM(AD19:AE19) -> 1045.2 | AG19: =AF19/(60*24) -> 0.72583333 | AH19: =IFERROR(AE19/AF19,0) -> 0.36854191 | AI19: 44598 | AJ19: 21 | AK19: 930 | AL19: =IF(AM19=0,0,(+AI19*AK19/1000)) -> 41476.14 | AM19: =927-56 -> 871 | AN19: 6 | AO19: 0 | AP19: =25+33 -> 58 | AQ19: 0 | AR19: 30 | AS19: 0 | AT19: 14 | AU19: =12+76 -> 88 | AV19: =SUM(AO19:AU19) -> 190 | AW19: =+(AM19+(BR19*50/100))+(BS19*30/100)-BB19 -> 898.3 | AX19: 0 | AY19: 0 | AZ19: 0 | BA19: 0 | BB19: 0 | BC19: 0 | BD19: =17+15 -> 32 | BE19: 0 | BF19: 15 | BG19: 0 | BH19: 13 | BI19: =11+28 -> 39 | BJ19: =SUM(BC19:BI19) -> 99 | BK19: 33349 | BL19: =IFERROR(+BO19*1000/((BK19)*(BM19/1000)),0) -> 20.796677 | BM19: =AK19 -> 930 | BN19: =+BK19*BM19/1000 -> 31014.57 | BO19: =684.5-39.5 -> 645 | BP19: 0 | BQ19: 0 | BR19: =AO19-BC19 -> 0 | BS19: =(AP19+AQ19+AR19+AS19+AT19+AU19)-(BD19+BE19+BF19+BG19+BH19+BI19) -> 91 | BT19: =BR19+BS19 -> 91 | BU19: =IFERROR(+BK19/AE19,0) -> 86.575805 | BV19: =IFERROR(+BK19/(AF19),0) -> 31.906812 | BW19: =IFERROR(+(AI19-AZ19)-BK19,0) -> 11249 | BX19: =IFERROR(+BW19/BK19,0) -> 0.33731146 | BY19: =IFERROR(+(AL19-BA19)-BN19,0) -> 10461.57 | BZ19: =IFERROR(+BY19/BN19,0) -> 0.33731146 | CA19: =IFERROR(+AW19-(BO19),0) -> 253.3 | CB19: =IFERROR(+CA19/BO19,1) -> 0.39271318 | CC19: 0 | CD19: 0 | CE19: al mmento de registrar estac 2 no mueve registros en ninguna direccion, y estac 5 solo mueve 5 mm hacia adelante, color negro problemas de sucio por secado acelerado, por esto se realizan varias paradas por limpieza y se cambia tinta pvk por cromia, mejorando pero luego vuelve a ensuciar, se limpia tambor central por sucio del barniz y el rodillo presor no ejercia su funcion bien, falta de ptos color negro se baja plancha y se monta una nueva, limpieza de planha por sucio del color negro, bob 2 arroja 39 kg de dsp y bob 3 13 kg por sucio color negro, | CF19: REPETICION | CG19: 3 | CH19: =IFERROR((BT19*1000)/BN19,"") -> 2.9341048 | CI19: 3500 | CJ19: =IF(BW19=0,"",CI19-BW19) -> -7749 | CK19: {=_xlfn.IFS(CJ19>0,"CUMPLE",CJ19<0,"NO CUMPLE",CJ19="","")} -> NO CUMPLE | CL19: 46111 | CM19: {=_xlfn.IFS(CL19-C19 > 0,"CUMPLE",CL19-C19 < 0,"NO CUMPLE")} -> NO CUMPLE | CN19: 36000 | CO19: =BK19-CN19 -> -2651 | CP19: 0 | CQ19: TELEPLASTIC | CR19: BOPP POCT PERLADO
A20: 01-6051 | B20: OF | C20: 46134 | D20: =IFERROR(VLOOKUP($A20,Hoja3!$A$3:$F$6000,2,FALSE),"") -> TXPCGP023B001 | E20: 16589 | F20: =IFERROR(VLOOKUP($A20,Hoja3!$A$3:$F$6000,6,FALSE),"") -> CORTE | G20: 1 | H20: =IFERROR(VLOOKUP($A20,Hoja3!$A$3:$F$6000,5,FALSE),"") -> CX | I20: =IFERROR(VLOOKUP($A20,Hoja3!$A$3:$F$6000,3,FALSE),"") -> PEPSI-COLA VENEZUELA, C.A. | J20: =IFERROR(VLOOKUP($A20,Hoja3!$A$3:$F$6000,4,FALSE),"") -> ETIQUETA IMPRESA GOLDEN PIÑA 1,5L | K20: 450 | L20: 30 | M20: 0 | N20: 0 | O20: 10 | P20: 0 | Q20: 0 | R20: 0 | S20: =70+10+10 -> 90 | T20: 0 | U20: 0 | V20: 0 | W20: 0 | X20: 0 | Y20: 0 | Z20: 0 | AA20: 0 | AB20: 0 | AC20: 0 | AD20: =SUM(L20:AC20) -> 130 | AE20: 140.4 | AF20: =SUM(AD20:AE20) -> 270.4 | AG20: =AF20/(60*24) -> 0.18777778 | AH20: =IFERROR(AE20/AF20,0) -> 0.51923077 | AI20: 25881 | AJ20: 21 | AK20: 930 | AL20: =IF(AM20=0,0,(+AI20*AK20/1000)) -> 24069.33 | AM20: =469+56 -> 525 | AN20: 6 | AO20: 0 | AP20: =17+15 -> 32 | AQ20: 0 | AR20: 15 | AS20: 0 | AT20: 13 | AU20: =11+28 -> 39 | AV20: =SUM(AO20:AU20) -> 99 | AW20: =+(AM20+(BR20*50/100))+(BS20*30/100)-BB20 -> 540.6 | AX20: 0 | AY20: 0 | AZ20: 0 | BA20: 0 | BB20: 0 | BC20: 0 | BD20: =12+5 -> 17 | BE20: 0 | BF20: 7 | BG20: 0 | BH20: 12 | BI20: =10+1 -> 11 | BJ20: =SUM(BC20:BI20) -> 47 | BK20: 24118 | BL20: =IFERROR(+BO20*1000/((BK20)*(BM20/1000)),0) -> 22.737669 | BM20: =AK20 -> 930 | BN20: =+BK20*BM20/1000 -> 22429.74 | BO20: 510 | BP20: 0 | BQ20: 0 | BR20: =AO20-BC20 -> 0 | BS20: =(AP20+AQ20+AR20+AS20+AT20+AU20)-(BD20+BE20+BF20+BG20+BH20+BI20) -> 52 | BT20: =BR20+BS20 -> 52 | BU20: =IFERROR(+BK20/AE20,0) -> 171.78063 | BV20: =IFERROR(+BK20/(AF20),0) -> 89.193787 | BW20: =IFERROR(+(AI20-AZ20)-BK20,0) -> 1763 | BX20: =IFERROR(+BW20/BK20,0) -> 0.07309893 | BY20: =IFERROR(+(AL20-BA20)-BN20,0) -> 1639.59 | BZ20: =IFERROR(+BY20/BN20,0) -> 0.07309893 | CA20: =IFERROR(+AW20-(BO20),0) -> 30.6 | CB20: =IFERROR(+CA20/BO20,1) -> 0.06 | CC20: 0 | CD20: 0 | CE20: se limpan planchas del negro por sucio | CF20: REPETICION | CG20: 3 | CH20: =IFERROR((BT20*1000)/BN20,"") -> 2.3183505 | CI20: 3500 | CJ20: =IF(BW20=0,"",CI20-BW20) -> 1737 | CK20: {=_xlfn.IFS(CJ20>0,"CUMPLE",CJ20<0,"NO CUMPLE",CJ20="","")} -> CUMPLE | CL20: 46111 | CM20: {=_xlfn.IFS(CL20-C20 > 0,"CUMPLE",CL20-C20 < 0,"NO CUMPLE")} -> NO CUMPLE | CN20: 20500 | CO20: =BK20-CN20 -> 3618 | CP20: 0 | CQ20: TELEPLASTIC | CR20: BOPP POCT PERLADO
A21: 000lm | B21: OF | C21: 46134 | D21: =IFERROR(VLOOKUP($A21,Hoja3!$A$3:$F$6000,2,FALSE),"") -> 000LM | E21: 000lm | F21: =IFERROR(VLOOKUP($A21,Hoja3!$A$3:$F$6000,6,FALSE),"") -> LIMPIEZA | G21: 0 | H21: =IFERROR(VLOOKUP($A21,Hoja3!$A$3:$F$6000,5,FALSE),"") -> CX | I21: =IFERROR(VLOOKUP($A21,Hoja3!$A$3:$F$6000,3,FALSE),"") -> LIMPIEZA GENERAL DE MAQUINA | J21: =IFERROR(VLOOKUP($A21,Hoja3!$A$3:$F$6000,4,FALSE),"") -> LIMPIEZA GENERAL DE MAQUINA | K21: 0 | L21: 0 | M21: 0 | N21: 0 | O21: 0 | P21: 0 | Q21: 150 | R21: 0 | S21: 0 | T21: 0 | U21: 0 | V21: 0 | W21: 0 | X21: 0 | Y21: 0 | Z21: 0 | AA21: 0 | AB21: 0 | AC21: 0 | AD21: =SUM(L21:AC21) -> 150 | AE21: 0 | AF21: =SUM(AD21:AE21) -> 150 | AG21: =AF21/(60*24) -> 0.10416667 | AH21: =IFERROR(AE21/AF21,0) -> 0 | AI21: 0 | AK21: 0 | AL21: =IF(AM21=0,0,(+AI21*AK21/1000)) -> 0 | AM21: 0 | AN21: 0 | AO21: 0 | AQ21: 0 | AR21: 0 | AS21: 0 | AT21: 0 | AU21: 0 | AV21: =SUM(AO21:AU21) -> 0 | AW21: =+(AM21+(BR21*50/100))+(BS21*30/100)-BB21 -> 0 | AX21: 0 | AY21: 0 | AZ21: 0 | BA21: 0 | BB21: 0 | BC21: 0 | BD21: 0 | BE21: 0 | BF21: 0 | BG21: 0 | BI21: 0 | BJ21: =SUM(BC21:BI21) -> 0 | BK21: 0 | BL21: =IFERROR(+BO21*1000/((BK21)*(BM21/1000)),0) -> 0 | BM21: 0 | BN21: =+BK21*BM21/1000 -> 0 | BO21: 0 | BP21: 0 | BQ21: 0 | BR21: =AO21-BC21 -> 0 | BS21: =(AP21+AQ21+AR21+AS21+AT21+AU21)-(BD21+BE21+BF21+BG21+BH21+BI21) -> 0 | BT21: =BR21+BS21 -> 0 | BU21: =IFERROR(+BK21/AE21,0) -> 0 | BV21: =IFERROR(+BK21/(AF21),0) -> 0 | BW21: =IFERROR(+(AI21-AZ21)-BK21,0) -> 0 | BX21: =IFERROR(+BW21/BK21,0) -> 0 | BY21: =IFERROR(+(AL21-BA21)-BN21,0) -> 0 | BZ21: =IFERROR(+BY21/BN21,0) -> 0 | CA21: =IFERROR(+AW21-(BO21),0) -> 0 | CB21: =IFERROR(+CA21/BO21,1) -> 1 | CC21: 0 | CD21: 0 | CE21: limpieza general de maquina | CF21: REPETICION | CG21: 0 | CH21: 0 | CI21: 3500 | CJ21: 0 | CK21: {=_xlfn.IFS(CJ21>0,"CUMPLE",CJ21<0,"NO CUMPLE",CJ21="","")} -> #N/A | CL21: 0 | CN21: 0 | CP21: 0
A22: 01-6023 | B22: OP | C22: 46139 | D22: =IFERROR(VLOOKUP($A22,Hoja3!$A$3:$F$6000,2,FALSE),"") -> TMAHSC083C003 | E22: 16567R | F22: =IFERROR(VLOOKUP($A22,Hoja3!$A$3:$F$6000,6,FALSE),"") -> LAMINACION | G22: 1 | H22: =IFERROR(VLOOKUP($A22,Hoja3!$A$3:$F$6000,5,FALSE),"") -> MCL | I22: =IFERROR(VLOOKUP($A22,Hoja3!$A$3:$F$6000,3,FALSE),"") -> ALIMENTOS HEINZ, C.A. | J22: =IFERROR(VLOOKUP($A22,Hoja3!$A$3:$F$6000,4,FALSE),"") -> LAMINACION IMPRESA GELATINA SONRISSA FRAMBUESA 132g. | K22: 274 | L22: 60 | M22: 0 | N22: 0 | O22: =20+20 -> 40 | P22: 130 | Q22: 0 | R22: 0 | S22: 0 | T22: 0 | U22: 0 | V22: 0 | W22: 0 | X22: =40+30 -> 70 | Y22: 0 | Z22: 0 | AA22: 0 | AB22: 0 | AC22: 0 | AD22: =SUM(L22:AC22) -> 300 | AE22: 220.2 | AF22: =SUM(AD22:AE22) -> 520.2 | AG22: =AF22/(60*24) -> 0.36125 | AH22: =IFERROR(AE22/AF22,0) -> 0.42329873 | AI22: 14000 | AJ22: 83 | AK22: 243 | AL22: =IF(AM22=0,0,(+AI22*AK22/1000)) -> 3402 | AM22: 273 | AN22: 1 | AO22: 0 | AP22: 0 | AQ22: 0 | AR22: 0 | AS22: 0 | AT22: 0 | AU22: 94 | AV22: =SUM(AO22:AU22) -> 94 | AW22: =+(AM22+(BR22*50/100))+(BS22*30/100)-BB22 -> 275.1 | AX22: 0 | AY22: 0 | AZ22: 0 | BA22: 0 | BB22: 0 | BC22: 0 | BD22: 0 | BE22: 0 | BF22: 0 | BG22: 0 | BH22: 0 | BI22: 87 | BJ22: =SUM(BC22:BI22) -> 87 | BK22: 13991 | BL22: =IFERROR(+BO22*1000/((BK22)*(BM22/1000)),0) -> 80.857388 | BM22: =AK22 -> 243 | BN22: =+BK22*BM22/1000 -> 3399.813 | BO22: 274.9 | BP22: 0 | BQ22: 0 | BR22: =AO22-BC22 -> 0 | BS22: =(AP22+AQ22+AR22+AS22+AT22+AU22)-(BD22+BE22+BF22+BG22+BH22+BI22) -> 7 | BT22: =BR22+BS22 -> 7 | BU22: =IFERROR(+BK22/AE22,0) -> 63.537693 | BV22: =IFERROR(+BK22/(AF22),0) -> 26.895425 | BW22: =IFERROR(+(AI22-AZ22)-BK22,0) -> 9 | BX22: =IFERROR(+BW22/BK22,0) -> 0.00064327067 | BY22: =IFERROR(+(AL22-BA22)-BN22,0) -> 2.187 | BZ22: =IFERROR(+BY22/BN22,0) -> 0.00064327067 | CA22: =IFERROR(+AW22-(BO22),0) -> 0.2 | CB22: =IFERROR(+CA22/BO22,1) -> 0.00072753729 | CC22: 0 | CD22: 0 | CE22: aplicacionde compuesto deslizante por cara interna para mejorar cof | CF22: PROCESO | CG22: 0 | CH22: =IFERROR((BT22*1000)/BN22,"") -> 2.0589368 | CI22: 0 | CJ22: =IF(BW22=0,"",CI22-BW22) -> -9 | CK22: {=_xlfn.IFS(CJ22>0,"CUMPLE",CJ22<0,"NO CUMPLE",CJ22="","")} -> NO CUMPLE | CL22: 0 | CN22: 0 | CP22: 0
A23: 21-0570 | B23: OP | C23: 46140 | D23: =IFERROR(VLOOKUP($A23,Hoja3!$A$3:$F$6000,2,FALSE),"") -> TXSPBC050A003 | E23: 16594 | F23: =IFERROR(VLOOKUP($A23,Hoja3!$A$3:$F$6000,6,FALSE),"") -> LAMINACION | G23: 1 | H23: =IFERROR(VLOOKUP($A23,Hoja3!$A$3:$F$6000,5,FALSE),"") -> CX | I23: =IFERROR(VLOOKUP($A23,Hoja3!$A$3:$F$6000,3,FALSE),"") -> C.A. SUCESORA DE JOSE PUIG & CIA | J23: =IFERROR(VLOOKUP($A23,Hoja3!$A$3:$F$6000,4,FALSE),"") -> LAMINACION IMPRESA BROWNIES CHOCOLATE 175g | K23: 1930 | L23: 10 | M23: 0 | N23: 0 | O23: 25 | P23: =40+55 -> 95 | Q23: 0 | R23: 0 | S23: 0 | T23: 0 | U23: 0 | V23: 0 | W23: 0 | X23: 0 | Y23: 0 | Z23: 0 | AA23: 0 | AB23: 0 | AC23: 0 | AD23: =SUM(L23:AC23) -> 130 | AE23: 370 | AF23: =SUM(AD23:AE23) -> 500 | AG23: =AF23/(60*24) -> 0.34722222 | AH23: =IFERROR(AE23/AF23,0) -> 0.74 | AI23: 38813 | AJ23: 50 | AK23: 1000 | AL23: =IF(AM23=0,0,(+AI23*AK23/1000)) -> 38813 | AM23: 1952.8 | AN23: 1 | AO23: 0 | AP23: 0 | AQ23: 0 | AR23: 0 | AS23: 0 | AT23: 0 | AU23: 87 | AV23: =SUM(AO23:AU23) -> 87 | AW23: =+(AM23+(BR23*50/100))+(BS23*30/100)-BB23 -> 1966.9 | AX23: 0 | AY23: 0 | AZ23: 0 | BA23: 0 | BB23: 0 | BC23: 0 | BD23: 0 | BE23: 0 | BF23: 0 | BG23: 0 | BH23: 0 | BI23: 40 | BJ23: =SUM(BC23:BI23) -> 40 | BK23: 38361 | BL23: =IFERROR(+BO23*1000/((BK23)*(BM23/1000)),0) -> 50.34801 | BM23: =AK23 -> 1000 | BN23: =+BK23*BM23/1000 -> 38361 | BO23: 1931.4 | BP23: 0 | BQ23: 0 | BR23: =AO23-BC23 -> 0 | BS23: =(AP23+AQ23+AR23+AS23+AT23+AU23)-(BD23+BE23+BF23+BG23+BH23+BI23) -> 47 | BT23: =BR23+BS23 -> 47 | BU23: =IFERROR(+BK23/AE23,0) -> 103.67838 | BV23: =IFERROR(+BK23/(AF23),0) -> 76.722 | BW23: =IFERROR(+(AI23-AZ23)-BK23,0) -> 452 | BX23: =IFERROR(+BW23/BK23,0) -> 0.0117828 | BY23: =IFERROR(+(AL23-BA23)-BN23,0) -> 452 | BZ23: =IFERROR(+BY23/BN23,0) -> 0.0117828 | CA23: =IFERROR(+AW23-(BO23),0) -> 35.5 | CB23: =IFERROR(+CA23/BO23,1) -> 0.018380449 | CC23: 0 | CD23: 0 | CE23: aplicación compuesto deslizante | CF23: PROCESO | CG23: 0 | CH23: =IFERROR((BT23*1000)/BN23,"") -> 1.2252027 | CI23: 0 | CJ23: =IF(BW23=0,"",CI23-BW23) -> -452 | CK23: {=_xlfn.IFS(CJ23>0,"CUMPLE",CJ23<0,"NO CUMPLE",CJ23="","")} -> NO CUMPLE | CL23: 0 | CN23: 0 | CP23: 0
A24: 01-6104 | B24: OF | C24: 46141 | D24: =IFERROR(VLOOKUP($A24,Hoja3!$A$3:$F$6000,2,FALSE),"") -> TXCLCM025A001 | E24: 16639 | F24: =IFERROR(VLOOKUP($A24,Hoja3!$A$3:$F$6000,6,FALSE),"") -> CORTE | G24: 1 | H24: =IFERROR(VLOOKUP($A24,Hoja3!$A$3:$F$6000,5,FALSE),"") -> cx | I24: =IFERROR(VLOOKUP($A24,Hoja3!$A$3:$F$6000,3,FALSE),"") -> CELOVEN, C.A. | J24: =IFERROR(VLOOKUP($A24,Hoja3!$A$3:$F$6000,4,FALSE),"") -> BOPP IMPRESO CINTA MRW | K24: 500 | L24: 70 | M24: 0 | N24: 40 | O24: 0 | P24: 0 | Q24: 0 | R24: 0 | S24: 0 | T24: 0 | U24: 0 | V24: 0 | W24: 0 | X24: 0 | Y24: 0 | Z24: 80 | AA24: 60 | AB24: 0 | AC24: 0 | AD24: =SUM(L24:AC24) -> 250 | AE24: 200.4 | AF24: =SUM(AD24:AE24) -> 450.4 | AG24: =AF24/(60*24) -> 0.31277778 | AH24: =IFERROR(AE24/AF24,0) -> 0.44493783 | AI24: 24000 | AJ24: 22 | AK24: 1020 | AL24: =IF(AM24=0,0,(+AI24*AK24/1000)) -> 24480 | AM24: 557 | AN24: 2 | AO24: 0 | AP24: 33 | AQ24: 0 | AR24: 0 | AS24: 0 | AT24: 23 | AU24: 0 | AV24: =SUM(AO24:AU24) -> 56 | AW24: =+(AM24+(BR24*50/100))+(BS24*30/100)-BB24 -> 564.2 | AX24: 0 | AY24: 0 | AZ24: 0 | BA24: 0 | BB24: 0 | BC24: 0 | BD24: 13 | BE24: 0 | BF24: 0 | BG24: 0 | BH24: 19 | BI24: 0 | BJ24: =SUM(BC24:BI24) -> 32 | BK24: 23508 | BL24: =IFERROR(+BO24*1000/((BK24)*(BM24/1000)),0) -> 22.603903 | BM24: =AK24 -> 1020 | BN24: =+BK24*BM24/1000 -> 23978.16 | BO24: 542 | BP24: 0 | BQ24: 0 | BR24: =AO24-BC24 -> 0 | BS24: =(AP24+AQ24+AR24+AS24+AT24+AU24)-(BD24+BE24+BF24+BG24+BH24+BI24) -> 24 | BT24: =BR24+BS24 -> 24 | BU24: =IFERROR(+BK24/AE24,0) -> 117.30539 | BV24: =IFERROR(+BK24/(AF24),0) -> 52.193606 | BW24: =IFERROR(+(AI24-AZ24)-BK24,0) -> 492 | BX24: =IFERROR(+BW24/BK24,0) -> 0.020929045 | BY24: =IFERROR(+(AL24-BA24)-BN24,0) -> 501.84 | BZ24: =IFERROR(+BY24/BN24,0) -> 0.020929045 | CA24: =IFERROR(+AW24-(BO24),0) -> 22.2 | CB24: =IFERROR(+CA24/BO24,1) -> 0.04095941 | CC24: 0 | CD24: 0 | CE24: Aprobacion, se culmina sin novedad | CF24: APROBACION | CG24: 2 | CH24: =IFERROR((BT24*1000)/BN24,"") -> 1.0009108 | CI24: 3500 | CJ24: =IF(BW24=0,"",CI24-BW24) -> 3008 | CK24: {=_xlfn.IFS(CJ24>0,"CUMPLE",CJ24<0,"NO CUMPLE",CJ24="","")} -> CUMPLE | CL24: 21-05-2026 | CM24: {=_xlfn.IFS(CL24-C24 > 0,"CUMPLE",CL24-C24 < 0,"NO CUMPLE")} -> CUMPLE | CN24: 20000 | CO24: =BK24-CN24 -> 3508 | CP24: 0 | CQ24: CELOVEN | CR24: BOPP TRANSPARENTE
A25: 000f | B25: OF | C25: 46142 | D25: =IFERROR(VLOOKUP($A25,Hoja3!$A$3:$F$6000,2,FALSE),"") -> 000F | E25: 000f | F25: =IFERROR(VLOOKUP($A25,Hoja3!$A$3:$F$6000,6,FALSE),"") -> TODAS | G25: 0 | H25: =IFERROR(VLOOKUP($A25,Hoja3!$A$3:$F$6000,5,FALSE),"") -> MCL | I25: =IFERROR(VLOOKUP($A25,Hoja3!$A$3:$F$6000,3,FALSE),"") -> FALTA DE PEDIDOS / INSUMOS | J25: =IFERROR(VLOOKUP($A25,Hoja3!$A$3:$F$6000,4,FALSE),"") -> FALTA DE PEDIDOS / INSUMOS | K25: 0 | L25: 0 | M25: 0 | N25: 0 | O25: 0 | P25: 0 | Q25: 0 | R25: 0 | S25: 0 | T25: 0 | U25: 0 | V25: 0 | W25: 0 | X25: 0 | Y25: 0 | Z25: 0 | AA25: 0 | AB25: 0 | AC25: 21914 | AD25: =SUM(L25:AC25) -> 21914 | AE25: 0 | AF25: =SUM(AD25:AE25) -> 21914 | AG25: =AF25/(60*24) -> 15.218056 | AH25: =IFERROR(AE25/AF25,0) -> 0 | AI25: 0 | AJ25: 0 | AK25: 0 | AL25: =IF(AM25=0,0,(+AI25*AK25/1000)) -> 0 | AM25: 0 | AN25: 0 | AO25: 0 | AP25: 0 | AQ25: 0 | AR25: 0 | AS25: 0 | AT25: 0 | AU25: 0 | AV25: 0 | AW25: 0 | AX25: 0 | AY25: 0 | AZ25: 0 | BA25: 0 | BB25: 0 | BC25: 0 | BD25: 0 | BE25: 0 | BF25: 0 | BG25: 0 | BH25: 0 | BI25: 0 | BJ25: 0 | BK25: 0 | BL25: 0 | BM25: 0 | BN25: 0 | BO25: 0 | BP25: 0 | BQ25: 0 | BR25: 0 | BS25: 0 | BT25: 0 | BU25: 0 | BV25: 0 | BW25: =IFERROR(+(AI25-AZ25)-BK25,0) -> 0 | BX25: =IFERROR(+BW25/BK25,0) -> 0 | BY25: =IFERROR(+(AL25-BA25)-BN25,0) -> 0 | BZ25: =IFERROR(+BY25/BN25,0) -> 0 | CA25: =IFERROR(+AW25-(BO25),0) -> 0 | CB25: =IFERROR(+CA25/BO25,1) -> 1 | CC25: 0 | CD25: 0 | CE25: parada por falta de insumo/pedido | CF25: FALTA DE INSUMO | CG25: 0 | CH25: 0 | CI25: 0 | CJ25: 0 | CK25: 0 | CL25: 0 | CM25: {=_xlfn.IFS(CL25-C25 > 0,"CUMPLE",CL25-C25 < 0,"NO CUMPLE")} -> NO CUMPLE | CN25: 0 | CO25: =BK25-CN25 -> 0 | CP25: 0
D26: =IFERROR(VLOOKUP($A26,Hoja3!$A$3:$F$6000,2,FALSE),"") | F26: =IFERROR(VLOOKUP($A26,Hoja3!$A$3:$F$6000,6,FALSE),"") | H26: =IFERROR(VLOOKUP($A26,Hoja3!$A$3:$F$6000,5,FALSE),"") | I26: =IFERROR(VLOOKUP($A26,Hoja3!$A$3:$F$6000,3,FALSE),"") | J26: =IFERROR(VLOOKUP($A26,Hoja3!$A$3:$F$6000,4,FALSE),"") | AD26: =SUM(L26:AC26) -> 0 | AF26: =SUM(AD26:AE26) -> 0 | AG26: =AF26/(60*24) -> 0 | AH26: =IFERROR(AE26/AF26,0) -> 0 | AL26: =IF(AM26=0,0,(+AI26*AK26/1000)) -> 0 | AV26: =SUM(AO26:AU26) -> 0 | AW26: =+(AM26+(BR26*50/100))+(BS26*30/100)-BB26 -> 0 | BJ26: =SUM(BC26:BI26) -> 0 | BM26: =AK26 -> 0 | BN26: =+BK26*BM26/1000 -> 0 | BR26: =AO26-BC26 -> 0 | BS26: =(AP26+AQ26+AR26+AS26+AT26+AU26)-(BD26+BE26+BF26+BG26+BH26+BI26) -> 0 | BT26: =BR26+BS26 -> 0 | BW26: =IFERROR(+(AI26-AZ26)-BK26,0) -> 0 | BX26: =IFERROR(+BW26/BK26,0) -> 0 | BY26: =IFERROR(+(AL26-BA26)-BN26,0) -> 0 | BZ26: =IFERROR(+BY26/BN26,0) -> 0 | CA26: =IFERROR(+AW26-(BO26),0) -> 0 | CB26: =IFERROR(+CA26/BO26,1) -> 1 | CC26: 0 | CD26: 0 | CH26: =IFERROR((BT26*1000)/BN26,"") | CM26: {=_xlfn.IFS(CL26-C26 > 0,"CUMPLE",CL26-C26 < 0,"NO CUMPLE")} -> #N/A | CO26: =BK26-CN26 -> 0
I27: =IFERROR(VLOOKUP($A27,Hoja3!$A$3:$F$6000,3,FALSE),"") | J27: =IFERROR(VLOOKUP($A27,Hoja3!$A$3:$F$3998,4,FALSE),"") | AL27: =IF(AM27=0,0,(+AI27*AK27/1000)) -> 0 | AZ27: =IF(BB27=0,0,BB27/((AJ27/1000)*(AK27/1000))) -> 0 | BA27: =AZ27*BM27/1000 -> 0 | CH27: =IFERROR((BT27*1000)/BN27,"") | CJ27: =IFERROR((BT27*1000)/BN27,"") | CK27: =IFERROR((((BR27*0.5)+(BS27*0.3))*1000)/BN27,"") | CO27: =BK27-CN27 -> 0
A28: OF= OLYMPIA FINAL | E28: Numeros de trabajos= | G28: =SUM(G15:G26) -> 9 | I28: =IFERROR(VLOOKUP($A28,Hoja3!$A$3:$F$6000,3,FALSE),"") | J28: =IFERROR(VLOOKUP($A28,Hoja3!$A$3:$F$3998,4,FALSE),"") | K28: =SUM(K15:K26) -> 14344 | L28: =SUM(L15:L26) -> 600 | M28: =SUM(M15:M26) -> 515 | N28: =SUM(N15:N26) -> 380 | O28: =SUM(O15:O26) -> 160 | P28: =SUM(P15:P26) -> 440 | Q28: =SUM(Q15:Q26) -> 150 | R28: =SUM(R15:R26) -> 0 | ... AG28: =SUM(AG15:AG26) -> 20.000139 | AH28: =IFERROR(AE28/AF29,0) -> 0.10820064 | AI28: =SUM(AI15:AI26) -> 405912 | AL28: =SUM(AL15:AL26) -> 406956.07 | AM28: =SUM(AM15:AM26) -> 12994.6 | AN28: =SUM(AN15:AN26) -> 24 | AV28: =SUM(AV15:AV26) -> 1470 | AW28: =SUM(AW15:AW26) -> 13325.2 | AX28: =SUM(AX15:AX26) -> 0 | AY28: =SUM(AY15:AY26) -> 0 | AZ28: =SUM(AZ15:AZ26) -> 0 | BA28: =SUM(BA15:BA26) -> 0 | BB28: =SUM(BB15:BB26) -> 0 | BJ28: =SUM(BJ15:BJ26) -> 648 | BK28: =SUM(BK15:BK26) -> 361019 | BL28: =IFERROR(+BO28*1000/((BK28)*(BM28/1000)),0) -> 0 | BN28: =SUM(BN15:BN26) -> 360367.59 | BO28: =SUM(BO15:BO26) -> 12332 | BP28: =SUM(BP15:BP26) -> 0 | BQ28: =SUM(BQ15:BQ26) -> 0 | BR28: =SUM(BR15:BR26) -> 420 | BS28: =SUM(BS15:BS26) -> 402 | BT28: =SUM(BT15:BT26) -> 822 | BU28: =IFERROR(+BK28/AE28,0) -> 115.85232 | BV28: =BK28/(AF28-(AC28+Q28+W28)) -> 53.593866 | BW28: =IFERROR(AI28-AZ28,0)-BK28 -> 44893 | BX28: =IFERROR(+BW28/BK28,0) -> 0.1243508 | BY28: =IFERROR(AL28-BA28,0)-BN28 -> 46588.482 | BZ28: =IFERROR(+BY28/BN28,0) -> 0.12928044 | CA28: =IFERROR(+AW28-(BO28),0) -> 993.2 | CB28: =IFERROR(+CA28/BO28,0) -> 0.080538437 | CC28: =SUM(CC15:CC26) -> 0 | CD28: =SUM(CD15:CD26) -> 0 | CH28: =IFERROR((BT28*1000)/BN28,"") -> 2.2810043 | CI28: =SUM(CI15:CI26) -> 28000 | CJ28: =IFERROR((BT28*1000)/BN28,"") -> 2.2810043 | CK28: =IFERROR((((BR28*0.5)+(BS28*0.3))*1000)/BN28,"") -> 0.9173966 | CN28: =SUM(CN15:CN26) -> 319500 | CO28: =BK28-CN28 -> 41519
A29: OP= OLYMPIA PROCESO | I29: =IFERROR(VLOOKUP($A29,Hoja3!$A$3:$F$6000,3,FALSE),"") | J29: =IFERROR(VLOOKUP($A29,Hoja3!$A$3:$F$3998,4,FALSE),"") | K29: % EFICIENCIA | L29: =IFERROR(L28/AF29,0) -> 0.020833189 | M29: =IFERROR(M28/AF29,0) -> 0.01788182 | N29: =(N28/AF29) -> 0.013194353 | O29: =(O28/AF29) -> 0.005555517 | P29: =(P28/AF29) -> 0.015277672 | Q29: =(Q28/AF29) -> 0.0052082972 | R29: =(R28/AF29) -> 0 | S29: =(S28/AF29) -> 0.011805474 | T29: =(T28/AF29) -> 0.001909709 | U29: =(U28/AF29) -> 0.00052082972 | V29: =(V28/AF29) -> 0.013367963 | W29: =(W28/AF29) -> 0 | X29: =(X28/AF29) -> 0.010416594 | Y29: =(Y28/AF29) -> 0 | Z29: =(Z28/AF29) -> 0.0027777585 | AA29: =(AA28/AF29) -> 0.0020833189 | AB29: =(AB28/AF28) -> 0.010069375 | AC29: =(AC28/AF28) -> 0.76089749 | AD29: =(AD28/AF29) -> 0.89179936 | AE29: =(AE28/AF29) -> 0.10820064 | AF29: =AF28 -> 28800.2 | AG29: =AF29/60/24 -> 20.000139 | AH29: <= Tiempo dedicado | BL29: =IFERROR(+BO29*1000/((BK29)*(BM29/1000)),0) -> 0
A30: Nota: | I30: =IFERROR(VLOOKUP($A30,Hoja3!$A$3:$F$6000,3,FALSE),"") | J30: =IFERROR(VLOOKUP($A30,Hoja3!$A$3:$F$3998,4,FALSE),"") | K30: Horas | L30: =(L28/60) -> 10 | M30: =(M28/60) -> 8.5833333 | N30: =(N28/60) -> 6.3333333 | O30: =(O28/60) -> 2.6666667 | P30: =(P28/60) -> 7.3333333 | Q30: =(Q28/60) -> 2.5 | R30: =(R28/60) -> 0 | S30: =(S28/60) -> 5.6666667 | ... AF30: =(AF28/60) -> 480.00333 | AG30: =AH30/60/24 -> -0.00013888889 | AH30: =D8-(AF28) -> -0.2 | BJ30: Meta | BK30: 2000000 | BL30: m/l | BZ30: Meta Desperdicio | CB30: 0.08 | CN30: TRABAJOS QUE NO CUMPLEN CON LA FECHA DE ENTREGA | CQ30: =COUNTIF(CM15:CM119,"NO CUMPLE") -> 3
A31: EL PROMEDIO DE METROS EN TERMINOS DE EFICIENCIA POR TURNO EN FUNCION AL TIEMPO DISPONIBLE ES DE | J31: =IFERROR(BK28/(C8*3),0) -> 6016.9833 | K31: Dias | L31: =(L30/24) -> 0.41666667 | M31: =(M30/24) -> 0.35763889 | N31: =(N30/24) -> 0.26388889 | O31: =(O30/24) -> 0.11111111 | P31: =(P30/24) -> 0.30555556 | Q31: =(Q30/24) -> 0.10416667 | R31: =(R30/24) -> 0 | S31: =(S30/24) -> 0.23611111 | ... AF31: =(AF30/24) -> 20.000139 | AG31: DIAS POR TRABAJAR | CN31: TRABAJOS CUMPLEN CON LA FECHA DE ENTREGA | CQ31: =COUNTIF(CM15:CM120,"CUMPLE") -> 5
A32: EL PROMEDIO DE METROS EN TERMINOS DE EFICIENCIA POR TURNO EN FUNCION AL TIEMPO DE TRABAJO ES DE | J32: =IFERROR(BK28/(ROUND(AE31,0)*3),0) -> 60169.833
A33: =IFERROR(L30/G28,0) -> 1.1111111 | AF33: min | AG33: Hrs | AH33: Dias
AC34: Tiempo Total de Parada por Limpieza de Maquina | AF34: =Q28 -> 150 | AG34: =Q30 -> 2.5 | AH34: =Q31 -> 0.10416667
D35: PROMEDIO DE TIEMPO DE PREPARACION POR TRABAJO => | I35: =IFERROR(L28/G28,0) -> 66.666667 | P35: suspendidos
K36: Numero de aprobaciones en el mes => | O36: =COUNTIFS(Z15:Z26,">0",CF15:CF26,"APROBACION") -> 1 | P36: =COUNTIFS(Z15:Z26,">0",CF15:CF26,"SUSPENDIDO") -> 0 | R36: Trabajos suspendidos en el mes => | V36: =P36+P37 -> 0 | AC36: Tiempo Total de Parada por Produccion | AF36: =(L28+M28+N28+S28+V28+T28+U28) -> 2290 | AG36: =(L30+M30+N30+S30+V30+T30+U30) -> 38.166667 | AH36: =(L31+M31+N31+S31+V31+T31+U31) -> 1.5902778
K37: Trabajos Repetidos en el mes => | O37: =COUNTIFS(CF15:CF26,"REPETICION")+COUNTIFS(CF15:CF26,"PROCESO") -> 9 | P37: =COUNTIFS(Z15:Z27,"=0",CF15:CF27,"SUSPENDIDO") -> 0
AC38: Tiempo Total de Parada por Proceso de Apoyo | AF38: =(O28+P28+R28+W28+X28+Y28+Z28+AB28+AA28) -> 1330 | AG38: =(O30+P30+R30+W30+X30+Y30+Z30+AB30+AA30) -> 22.166667 | AH38: =(O31+P31+R31+W31+X31+Y31+Z31+AB31+AA31) -> 0.92361111
AC39: Tiempo Total de Parada por Falta de Pedido | AF39: =AC28 -> 21914 | AG39: =AC30 -> 365.23333 | AH39: =AC31 -> 15.218056
AC40: Horas TRABAJADAS | AF40: =AE28 -> 3116.2 | AG40: =AE30 -> 51.936667 | AH40: =AE31 -> 2.1640278
AD41: TOTAL | AF41: =SUM(AF34:AF40) -> 28800.2 | AG41: =SUM(AG34:AG40) -> 480.00333 | AH41: =SUM(AH34:AH40) -> 20.000139

Sheet NOVOFLEX.
A3: INFORME MENSUAL DE PRODUCCION
D4: Disponibilidad | E4: Rendimiento | F4: Calidad | I4: OEE NOVOFLEX | N4: =D5 -> 0.92923611 | O4: =E5 -> 0.8596378 | P4: =F5 -> 0.90806147
A5: NOVOFLEX | D5: =(AF72-AC72-Q72)/D7 -> 0.92923611 | E5: =((BK72/(AF72-AC72-W72-Q72))/75) -> 0.8596378 | F5: =100%-CB72 -> 0.90806147 | I5: =N4*O4*P4 -> 0.72536539
A6: MES: | B6: MARZO
A7: DIAS TRABAJADOS : | C7: 20 | D7: =C7*24*60 -> 28800 | E7: =C7*24 -> 480
A8: PEDIDO | B8: CODIGO DE MAQUINA | C8: FECHA | D8: CODIGO PRODUCTO | E8: O/P | F8: DESTINO | G8: N° DE TRABAJOS | H8: COMPAÑÍA | I8: NOMBRE DEL CLIENTE | J8: PRODUCTO | K8: CLIENTE Kg | L8: TIEMPO DE PARADAS EN MINUTOS | AD8: TOTAL TIEMPO PARADAS min. | AE8: TIEMPO EFECTIVO PRODUCCION min. | AF8: TOTAL TIEMPO PRODUCCION min. | AG8: DIAS TRABAJADOS | AH8: EFICIENCIA DE MAQUINA | AI8: ENTRADA DE MATERIA PRIMA | AZ8: SALIDA DE MATERIALES | BR8: DATOS DE TINTA Kg. | BU8: VELOCIDAD m/min. | BW8: DESPERDICIO | CE8: OBSERVACIONES
L9: PREPARACION | M9: PRE-PRENSA | N9: COLORIMETRIA | O9: CALIDAD | P9: MANTENIMIENTO | Q9: Limpieza general de Maquina | R9: PLANIFICACION | S9: LIMPIEZA DE PLANCHA | T9: LIMPIEZA DE TAMBOR CENTRAL | U9: LIMPIEZA DE RODILLO | V9: PRODUCCION | W9: PRUEBAS | X9: LOGISTICA | Y9: FALLAS ELECT | Z9: APROBACIONES | AA9: ESTANDAR DE COLOR | AB9: RRHH | AC9: FALTA DE INSUMO/PEDIDO
AI10: PELICULAS | AN10: TINTAS Kg | AW10: CONSUMO | AX10: SOLVENTE Lts | AZ10: PELICULA DEVOLUCION | BC10: TINTAS KG EN DEVOLUCION | BK10: PRODUCTO TERMINADO | BP10: SOLVENTE Lts | BR10: CONSUMO DE TINTA BLANCO | BS10: CONSUMO DE TINTA VARIAS | BT10: CONSUMO TOTAL | BU10: VELOCIDAD DE MAQUINA TEORICA ML/min. | BV10: VELOCIDAD DE MAQUINA REAL ML/min. | BW10: m/l | BY10: m2 | CA10: Kg
AI11: m/l | AJ11: GRAMAJE g/m2 | AK11: ANCHO mm | AL11: m2 | AM11: Kg | AN11: # COLORES | AO11: BLANCO | AP11: AZUL REFLEX | AQ11: MAGENTA | AR11: AMARILLO | AS11: CYAN | AT11: ROJO | AU11: OTRAS | AV11: TOTAL | AX11: PRODUCCION | AY11: LIMPIEZA | AZ11: m/l | BA11: m2 | BB11: Kg | BC11: BLANCO | BD11: AZUL REFLEX | BE11: MAGENTA | BF11: AMARILLO | BG11: CYAN | BH11: ROJO | BI11: OTRAS | BJ11: TOTAL | BK11: m/l | BL11: GRAMAJE g/m2 | BM11: ANCHO mm | BN11: m2 | BO11: Kg | BP11: PRODUCCION | BQ11: LIMPIEZA
BK12: m/l | BW12: CANT | BX12: % | BY12: CANT | BZ12: % | CA12: CANT | CB12: % | CC12: MAT. OBSERVACION | CD12: MAT. RECHAZADO | CF12: Aplic Tinta Humeda | CG12: Tipo de Trabajo | CH12: nº de pantone | CI12: M/L Estandar de Dsp | CJ12: Metros de Dsp | CK12: Cumplimiento | CL12: fecha de entrega | CM12: cumplimiento entrega | CN12: metros op | CO12: Cumplimiento | CP12: material reciclado | CQ12: Proveedor | CR12: Material
K13: Trabajos Repetidos en el mes => | AF13: +
A14: 01-6072 | B14: NF | C14: 46113 | D14: =IFERROR(VLOOKUP($A14,Hoja3!$A$3:$F$6000,2,FALSE),"") -> TMAPAL121A001 | E14: 16606 | F14: =IFERROR(VLOOKUP($A14,Hoja3!$A$3:$F$6000,6,FALSE),"") -> LAMINACION | G14: 1 | H14: =IFERROR(VLOOKUP($A14,Hoja3!$A$3:$F$6000,5,FALSE),"") -> MCL | I14: =IFERROR(VLOOKUP($A14,Hoja3!$A$3:$F$6000,3,FALSE),"") -> ALIMENTOS POLAR COMERCIAL, C.A. | J14: =IFERROR(VLOOKUP($A14,Hoja3!$A$3:$F$6000,4,FALSE),"") -> ALUMINIO LAMINADO IMPRESO MAVESA 500g | K14: 8500 | L14: =15+20 -> 35 | M14: 15 | N14: 30 | O14: 15 | P14: 0 | Q14: 0 | R14: 0 | S14: =10+15+16+15+10+15 -> 81 | T14: 10 | U14: =15+15 -> 30 | V14: =10+15+20 -> 45 | W14: 0 | X14: 0 | Y14: 0 | Z14: 0 | AA14: 0 | AB14: 0 | AC14: 0 | AD14: =SUM(L14:AC14) -> 261 | AE14: 658.8 | AF14: =SUM(AD14:AE14) -> 919.8 | AG14: =AF14/(60*24) -> 0.63875 | AH14: =IFERROR(AE14/AF14,0) -> 0.71624266 | AI14: 91250 | AJ14: 102 | AK14: 920 | AL14: =IF(AM14=0,0,(+AI14*AK14/1000)) -> 83950 | AM14: 8693.5 | AN14: 7 | AO14: 370 | AP14: 17 | AQ14: 21 | AR14: 0 | AS14: 0 | AT14: 0 | AU14: =175+41+12+12 -> 240 | AV14: =SUM(AO14:AU14) -> 648 | AW14: =+(AM14+(BR14*50/100))+(BS14*30/100)-BB14 -> 8866.8 | AX14: 0 | AY14: 0 | AZ14: 0 | BA14: 0 | BB14: 0 | BC14: 135 | BD14: 11 | BE14: 10 | BF14: 0 | BG14: 0 | BH14: 0 | BI14: =52+8+6+5 -> 71 | BJ14: =SUM(BC14:BI14) -> 227 | BK14: 89112 | BL14: =IFERROR(+BO14*1000/((BK14)*(BM14/1000)),0) -> 104.85339 | BM14: =AK14 -> 920 | BN14: =+BK14*BM14/1000 -> 81983.04 | BO14: =8726.9-130.7 -> 8596.2 | BP14: 0 | BQ14: 0 | BR14: =AO14-BC14 -> 235 | BS14: =(AP14+AQ14+AR14+AS14+AT14+AU14)-(BD14+BE14+BF14+BG14+BH14+BI14) -> 186 | BT14: =BR14+BS14 -> 421 | BU14: =IFERROR(+BK14/AE14,0) -> 135.26412 | BV14: =IFERROR(+BK14/(AF14),0) -> 96.881931 | BW14: =IFERROR(+(AI14-AZ14)-BK14,0) -> 2138 | BX14: =IFERROR(+BW14/BK14,0) -> 0.023992279 | BY14: =IFERROR(+(AL14-BA14)-BN14,0) -> 1966.96 | BZ14: =IFERROR(+BY14/BN14,0) -> 0.023992279 | CA14: =IFERROR(+AW14-(BO14),0) -> 270.6 | CB14: =IFERROR(+CA14/BO14,1) -> 0.031479026 | CC14: 0 | CD14: 0 | CE14: Se realiza produccion a 130 m/m ya que a mayor velocidad presenta arrastre de el color blanco y azul | CF14: =IFERROR((BT14*1000)/BN14,"") -> 5.1352085 | CG14: REPETICION | CH14: 2 | CI14: 3500 | CJ14: =IF(BW14=0,"",CI14-BW14) -> 1362 | CK14: {=_xlfn.IFS(CJ14>0,"CUMPLE",CJ14<0,"NO CUMPLE",CJ14="","")} -> CUMPLE | CL14: 46139 | CM14: {=_xlfn.IFS(CL14-C14 > 0,"CUMPLE",CL14-C14 < 0,"NO CUMPLE")} -> CUMPLE | CN14: 91000 | CO14: =BK14-CN14 -> -1888 | CP14: 800 | CQ14: RETANA | CR14: ALUMINIO
A15: 000lm | B15: NF | C15: 46113 | D15: =IFERROR(VLOOKUP($A15,Hoja3!$A$3:$F$6000,2,FALSE),"") -> 000LM | E15: 000lm | F15: =IFERROR(VLOOKUP($A15,Hoja3!$A$3:$F$6000,6,FALSE),"") -> LIMPIEZA | G15: 0 | H15: =IFERROR(VLOOKUP($A15,Hoja3!$A$3:$F$6000,5,FALSE),"") -> CX | I15: =IFERROR(VLOOKUP($A15,Hoja3!$A$3:$F$6000,3,FALSE),"") -> LIMPIEZA GENERAL DE MAQUINA | J15: =IFERROR(VLOOKUP($A15,Hoja3!$A$3:$F$6000,4,FALSE),"") -> LIMPIEZA GENERAL DE MAQUINA | K15: 0 | L15: 0 | M15: 0 | N15: 0 | O15: 0 | P15: 0 | Q15: 665.2 | R15: 0 | S15: 0 | T15: 0 | U15: 0 | V15: 0 | W15: 0 | X15: 0 | Y15: 0 | Z15: 0 | AA15: 0 | AB15: 0 | AC15: 0 | AD15: =SUM(L15:AC15) -> 665.2 | AE15: 0 | AF15: =SUM(AD15:AE15) -> 665.2 | AG15: =AF15/(60*24) -> 0.46194444 | AH15: =IFERROR(AE15/AF15,0) -> 0 | AI15: 0 | AJ15: 0 | AK15: 0 | AL15: =IF(AM15=0,0,(+AI15*AK15/1000)) -> 0 | AM15: 0 | AN15: 0 | AO15: 0 | AP15: 0 | AQ15: 0 | AR15: 0 | AS15: 0 | AT15: 0 | AU15: 0 | AV15: =SUM(AO15:AU15) -> 0 | AW15: =+(AM15+(BR15*50/100))+(BS15*30/100)-BB15 -> 0 | AX15: 0 | AY15: 0 | AZ15: 0 | BA15: 0 | BB15: 0 | BC15: 0 | BD15: 0 | BE15: 0 | BF15: 0 | BG15: 0 | BH15: 0 | BI15: 0 | BJ15: =SUM(BC15:BI15) -> 0 | BK15: 0 | BL15: =IFERROR(+BO15*1000/((BK15)*(BM15/1000)),0) -> 0 | BM15: =AK15 -> 0 | BN15: =+BK15*BM15/1000 -> 0 | BO15: 0 | BP15: 0 | BQ15: 0 | BR15: =AO15-BC15 -> 0 | BS15: =(AP15+AQ15+AR15+AS15+AT15+AU15)-(BD15+BE15+BF15+BG15+BH15+BI15) -> 0 | BT15: =BR15+BS15 -> 0 | BU15: =IFERROR(+BK15/AE15,0) -> 0 | BV15: =IFERROR(+BK15/(AF15),0) -> 0 | BW15: =IFERROR(+(AI15-AZ15)-BK15,0) -> 0 | BX15: =IFERROR(+BW15/BK15,0) -> 0 | BY15: =IFERROR(+(AL15-BA15)-BN15,0) -> 0 | BZ15: =IFERROR(+BY15/BN15,0) -> 0 | CA15: =IFERROR(+AW15-(BO15),0) -> 0 | CB15: =IFERROR(+CA15/BO15,1) -> 1 | CC15: 0 | CD15: 0 | CE15: se realiza limpieza general de maquina | CF15: =IFERROR((BT15*1000)/BN15,"") | CG15: LIMPIEZA | CH15: 0 | CI15: 0 | CJ15: 0 | CK15: 0 | CL15: 0 | CM15: 0 | CN15: 0 | CO15: 0 | CP15: 0
A16: 000pp | B16: NF | C16: 46113 | D16: =IFERROR(VLOOKUP($A16,Hoja3!$A$3:$F$6000,2,FALSE),"") -> 000PP | E16: 000pp | F16: =IFERROR(VLOOKUP($A16,Hoja3!$A$3:$F$6000,6,FALSE),"") -> TODAS | G16: 0 | H16: =IFERROR(VLOOKUP($A16,Hoja3!$A$3:$F$6000,5,FALSE),"") -> CX | I16: =IFERROR(VLOOKUP($A16,Hoja3!$A$3:$F$6000,3,FALSE),"") -> PARADA PROGRAMADA | J16: =IFERROR(VLOOKUP($A16,Hoja3!$A$3:$F$6000,4,FALSE),"") -> PARADA PROGRAMADA | K16: 0 | L16: 0 | M16: 0 | N16: 0 | O16: 0 | P16: 300 | Q16: 0 | R16: 0 | S16: 0 | T16: 0 | U16: 0 | V16: 0 | W16: 0 | X16: 0 | Y16: 0 | Z16: 0 | AA16: 0 | AB16: 0 | AC16: 0 | AD16: =SUM(L16:AC16) -> 300 | AE16: 0 | AF16: =SUM(AD16:AE16) -> 300 | AG16: =AF16/(60*24) -> 0.20833333 | AH16: =IFERROR(AE16/AF16,0) -> 0 | AI16: 0 | AJ16: 0 | AK16: 0 | AL16: 0 | AM16: 0 | AN16: 0 | AO16: 0 | AP16: 0 | AQ16: 0 | AR16: 0 | AS16: 0 | AT16: 0 | AU16: 0 | AV16: 0 | AW16: 0 | AX16: 0 | AY16: 0 | AZ16: 0 | BA16: 0 | BB16: 0 | BC16: 0 | BD16: 0 | BE16: 0 | BF16: 0 | BG16: 0 | BH16: 0 | BI16: 0 | BJ16: 0 | BK16: 0 | BL16: =IFERROR(+BO16*1000/((BK16)*(BM16/1000)),0) -> 0 | BM16: =AK16 -> 0 | BN16: =+BK16*BM16/1000 -> 0 | BO16: 0 | BP16: 0 | BQ16: 0 | BR16: =AO16-BC16 -> 0 | BS16: =(AP16+AQ16+AR16+AS16+AT16+AU16)-(BD16+BE16+BF16+BG16+BH16+BI16) -> 0 | BT16: =BR16+BS16 -> 0 | BU16: =IFERROR(+BK16/AE16,0) -> 0 | BV16: =IFERROR(+BK16/(AF16),0) -> 0 | BW16: =IFERROR(+(AI16-AZ16)-BK16,0) -> 0 | BX16: =IFERROR(+BW16/BK16,0) -> 0 | BY16: =IFERROR(+(AL16-BA16)-BN16,0) -> 0 | BZ16: =IFERROR(+BY16/BN16,0) -> 0 | CA16: =IFERROR(+AW16-(BO16),0) -> 0 | CB16: =IFERROR(+CA16/BO16,1) -> 1 | CC16: 0 | CD16: 0 | CE16: parada por mantenimiento y tecnico | CF16: 0 | CG16: PARADA PROGRAMADA | CH16: 0 | CI16: 0 | CJ16: 0 | CK16: 0 | CL16: 0 | CM16: 0 | CN16: 0 | CO16: =BK16-CN16 -> 0 | CP16: 0
A17: 01-6059 | B17: NF | C17: 46118 | D17: =IFERROR(VLOOKUP($A17,Hoja3!$A$3:$F$6000,2,FALSE),"") -> TXPCGU023A001 | E17: 16596 | F17: =IFERROR(VLOOKUP($A17,Hoja3!$A$3:$F$6000,6,FALSE),"") -> CORTE | G17: 1 | H17: =IFERROR(VLOOKUP($A17,Hoja3!$A$3:$F$6000,5,FALSE),"") -> CX | I17: =IFERROR(VLOOKUP($A17,Hoja3!$A$3:$F$6000,3,FALSE),"") -> PEPSI-COLA VENEZUELA, C.A. | J17: =IFERROR(VLOOKUP($A17,Hoja3!$A$3:$F$6000,4,FALSE),"") -> ETIQUETA IMPRESA GOLDEN UVA 2L | K17: 150 | L17: =180+30 -> 210 | M17: 0 | N17: 60 | O17: 20 | P17: =15+65 -> 80 | Q17: 0 | R17: 0 | S17: 20 | T17: 15 | U17: 0 | V17: =20+10 -> 30 | W17: 0 | X17: 30 | Y17: 0 | Z17: 0 | AA17: 0 | AB17: 0 | AC17: 0 | AD17: =SUM(L17:AC17) -> 465 | AE17: 39.6 | AF17: =SUM(AD17:AE17) -> 504.6 | AG17: =AF17/(60*24) -> 0.35041667 | AH17: =IFERROR(AE17/AF17,0) -> 0.078478002 | AI17: 10500 | AJ17: 21 | AK17: 1010 | AL17: =IF(AM17=0,0,(+AI17*AK17/1000)) -> 10605 | AM17: 228.5 | AN17: 7 | AO17: 0 | AP17: =13+13 -> 26 | AQ17: 0 | AR17: 0 | AS17: 0 | AT17: 13 | AU17: =10+18+16+190 -> 234 | AV17: =SUM(AO17:AU17) -> 273 | AW17: =+(AM17+(BR17*50/100))+(BS17*30/100)-BB17 -> 237.2 | AX17: 0 | AY17: 0 | AZ17: 0 | BA17: 0 | BB17: 0 | BC17: 0 | BD17: =11+12 -> 23 | BE17: 0 | BF17: 0 | BG17: 0 | BH17: 12 | BI17: =8+14+11+176 -> 209 | BJ17: =SUM(BC17:BI17) -> 244 | BK17: 7034 | BL17: =IFERROR(+BO17*1000/((BK17)*(BM17/1000)),0) -> 22.394762 | BM17: =AK17 -> 1010 | BN17: =+BK17*BM17/1000 -> 7104.34 | BO17: =165-5.9 -> 159.1 | BP17: 0 | BQ17: 0 | BR17: =AO17-BC17 -> 0 | BS17: =(AP17+AQ17+AR17+AS17+AT17+AU17)-(BD17+BE17+BF17+BG17+BH17+BI17) -> 29 | BT17: =BR17+BS17 -> 29 | BU17: =IFERROR(+BK17/AE17,0) -> 177.62626 | BV17: =IFERROR(+BK17/(AF17),0) -> 13.939754 | BW17: =IFERROR(+(AI17-AZ17)-BK17,0) -> 3466 | BX17: =IFERROR(+BW17/BK17,0) -> 0.4927495 | BY17: =IFERROR(+(AL17-BA17)-BN17,0) -> 3500.66 | BZ17: =IFERROR(+BY17/BN17,0) -> 0.4927495 | CA17: =IFERROR(+AW17-(BO17),0) -> 78.1 | CB17: =IFERROR(+CA17/BO17,1) -> 0.49088624 | CC17: 0 | CD17: 0 | CE17: rotura de material bobina virgen, movimiento de registros estac4 genera 20 kg de desp, se intercambia anilox rojo y violeta por raya en el fondo | CF17: =IFERROR((BT17*1000)/BN17,"") -> 4.0820118 | CG17: REPETICION | CH17: 5 | CI17: 3500 | CJ17: =IF(BW17=0,"",CI17-BW17) -> 34 | CK17: {=_xlfn.IFS(CJ17>0,"CUMPLE",CJ17<0,"NO CUMPLE",CJ17="","")} -> CUMPLE | CL17: 46111 | CM17: {=_xlfn.IFS(CL17-C17 > 0,"CUMPLE",CL17-C17 < 0,"NO CUMPLE")} -> NO CUMPLE | CN17: 7000 | CO17: =BK17-CN17 -> 34 | CP17: 900 | CQ17: TELEPLASTIC | CR17: BOPP POCT PERLADO
A18: 01-6060 | B18: NF | C18: 46118 | D18: =IFERROR(VLOOKUP($A18,Hoja3!$A$3:$F$6000,2,FALSE),"") -> TXPCGU023A001 | E18: 16597 | F18: =IFERROR(VLOOKUP($A18,Hoja3!$A$3:$F$6000,6,FALSE),"") -> CORTE | G18: 1 | H18: =IFERROR(VLOOKUP($A18,Hoja3!$A$3:$F$6000,5,FALSE),"") -> CX | I18: =IFERROR(VLOOKUP($A18,Hoja3!$A$3:$F$6000,3,FALSE),"") -> PEPSI-COLA VENEZUELA, C.A. | J18: =IFERROR(VLOOKUP($A18,Hoja3!$A$3:$F$6000,4,FALSE),"") -> ETIQUETA IMPRESA GOLDEN UVA 2L | K18: 150 | L18: 0 | M18: 0 | N18: 0 | O18: 0 | P18: 0 | Q18: 0 | R18: 0 | S18: =15+5 -> 20 | T18: 0 | U18: 0 | V18: 0 | W18: 0 | X18: 0 | Y18: 0 | Z18: 0 | AA18: 0 | AB18: 0 | AC18: 0 | AD18: =SUM(L18:AC18) -> 20 | AE18: 45 | AF18: =SUM(AD18:AE18) -> 65 | AG18: =AF18/(60*24) -> 0.045138889 | AH18: =IFERROR(AE18/AF18,0) -> 0.69230769 | AI18: 8300 | AJ18: 21 | AK18: 1010 | AL18: =IF(AM18=0,0,(+AI18*AK18/1000)) -> 8383 | AM18: 184 | AN18: 7 | AO18: 0 | AP18: =11+12 -> 23 | AQ18: 0 | AR18: 0 | AS18: 0 | AT18: 12 | AU18: =8+14+11+176 -> 209 | AV18: =SUM(AO18:AU18) -> 244 | AW18: =+(AM18+(BR18*50/100))+(BS18*30/100)-BB18 -> 192.7 | AX18: 0 | AY18: 0 | AZ18: 0 | BA18: 0 | BB18: 0 | BC18: 0 | BD18: =9+11 -> 20 | BE18: 0 | BF18: 0 | BG18: 0 | BH18: 11 | BI18: =6+10+6+162 -> 184 | BJ18: =SUM(BC18:BI18) -> 215 | BK18: 8000 | BL18: =IFERROR(+BO18*1000/((BK18)*(BM18/1000)),0) -> 23.762376 | BM18: =AK18 -> 1010 | BN18: =+BK18*BM18/1000 -> 8080 | BO18: 192 | BP18: 0 | BQ18: 0 | BR18: =AO18-BC18 -> 0 | BS18: =(AP18+AQ18+AR18+AS18+AT18+AU18)-(BD18+BE18+BF18+BG18+BH18+BI18) -> 29 | BT18: =BR18+BS18 -> 29 | BU18: =IFERROR(+BK18/AE18,0) -> 177.77778 | BV18: =IFERROR(+BK18/(AF18),0) -> 123.07692 | BW18: =IFERROR(+(AI18-AZ18)-BK18,0) -> 300 | BX18: =IFERROR(+BW18/BK18,0) -> 0.0375 | BY18: =IFERROR(+(AL18-BA18)-BN18,0) -> 303 | BZ18: =IFERROR(+BY18/BN18,0) -> 0.0375 | CA18: =IFERROR(+AW18-(BO18),0) -> 0.7 | CB18: =IFERROR(+CA18/BO18,1) -> 0.0036458333 | CC18: 0 | CD18: 0 | CE18: se culmina produccion sin novedad | CF18: =IFERROR((BT18*1000)/BN18,"") -> 3.5891089 | CG18: REPETICION | CH18: 0 | CI18: 3500 | CJ18: =IF(BW18=0,"",CI18-BW18) -> 3200 | CK18: {=_xlfn.IFS(CJ18>0,"CUMPLE",CJ18<0,"NO CUMPLE",CJ18="","")} -> CUMPLE | CL18: 46111 | CM18: {=_xlfn.IFS(CL18-C18 > 0,"CUMPLE",CL18-A18 < 0,"NO CUMPLE")} -> NO CUMPLE | CN18: 7000 | CO18: =BK18-CN18 -> 1000 | CP18: 0 | CQ18: TELEPLASTIC | CR18: BOPP POCT PERLADO
A19: 01-6001 | B19: NF | C19: 46118 | D19: =IFERROR(VLOOKUP($A19,Hoja3!$A$3:$F$6000,2,FALSE),"") -> TXDNTP066C001 | E19: 16547 | F19: =IFERROR(VLOOKUP($A19,Hoja3!$A$3:$F$6000,6,FALSE),"") -> LAMINACION | G19: 1 | H19: =IFERROR(VLOOKUP($A19,Hoja3!$A$3:$F$6000,5,FALSE),"") -> CX | I19: =IFERROR(VLOOKUP($A19,Hoja3!$A$3:$F$6000,3,FALSE),"") -> DISTRIBUIDORA NACIONAL 2000, C.A. | J19: =IFERROR(VLOOKUP($A19,Hoja3!$A$3:$F$6000,4,FALSE),"") -> LAMINACION IMPRESA CAFÉ ANZOATEGUI TOSTADO Y MOLIDO PREMIUM 500g | K19: 330 | L19: =30+60+30 -> 120 | M19: 70 | N19: 30 | O19: 20 | P19: 20 | Q19: 0 | R19: 0 | S19: =20+20 -> 40 | T19: 0 | U19: 0 | V19: =15 -> 15 | W19: 0 | X19: 0 | Y19: 0 | Z19: 0 | AA19: 0 | AB19: 0 | AC19: 0 | AD19: =SUM(L19:AC19) -> 315 | AE19: 90 | AF19: =SUM(AD19:AE19) -> 405 | AG19: =AF19/(60*24) -> 0.28125 | AH19: =IFERROR(AE19/AF19,0) -> 0.22222222 | AI19: 21200 | AJ19: 18 | AK19: 1000 | AL19: =IF(AM19=0,0,(+AI19*AK19/1000)) -> 21200 | AM19: 387 | AN19: 6 | AO19: 50 | AP19: 0 | AQ19: 25 | AR19: 16 | AS19: 0 | AT19: 10 | AU19: =22+15 -> 37 | AV19: =SUM(AO19:AU19) -> 138 | AW19: =+(AM19+(BR19*50/100))+(BS19*30/100)-BB19 -> 400.4 | AX19: 0 | AY19: 0 | AZ19: 0 | BA19: 0 | BB19: 0 | BC19: 40 | BD19: 0 | BE19: 21 | BF19: 8 | BG19: 0 | BH19: 7 | BI19: =13+11 -> 24 | BJ19: =SUM(BC19:BI19) -> 100 | BK19: 17264 | BL19: =IFERROR(+BO19*1000/((BK19)*(BM19/1000)),0) -> 18.75 | BM19: =AK19 -> 1000 | BN19: =+BK19*BM19/1000 -> 17264 | BO19: =345-21.3 -> 323.7 | BP19: 0 | BQ19: 0 | BR19: =AO19-BC19 -> 10 | BS19: =(AP19+AQ19+AR19+AS19+AT19+AU19)-(BD19+BE19+BF19+BG19+BH19+BI19) -> 28 | BT19: =BR19+BS19 -> 38 | BU19: =IFERROR(+BK19/AE19,0) -> 191.82222 | BV19: =IFERROR(+BK19/(AF19),0) -> 42.62716 | BW19: =IFERROR(+(AI19-AZ19)-BK19,0) -> 3936 | BX19: =IFERROR(+BW19/BK19,0) -> 0.22798888 | BY19: =IFERROR(+(AL19-BA19)-BN19,0) -> 3936 | BZ19: =IFERROR(+BY19/BN19,0) -> 0.22798888 | CA19: =IFERROR(+AW19-(BO19),0) -> 76.7 | CB19: =IFERROR(+CA19/BO19,1) -> 0.23694779 | CC19: 0 | CD19: 0 | CE19: vacio en manga color negro, falla en los extremos color rojo se cambia a daptador, limpieza color magenta y negro | CF19: =IFERROR((BT19*1000)/BN19,"") -> 2.2011121 | CG19: REPETICION | CH19: 1 | CI19: 3500 | CJ19: =IF(BW19=0,"",CI19-BW19) -> -436 | CK19: {=_xlfn.IFS(CJ19>0,"CUMPLE",CJ19<0,"NO CUMPLE",CJ19="","")} -> NO CUMPLE | CL19: 46143 | CM19: {=_xlfn.IFS(CL19-C19 > 0,"CUMPLE",CL19-A19 < 0,"NO CUMPLE")} -> CUMPLE | CN19: 18000 | CO19: =BK19-CN19 -> -736 | CP19: 1200 | CQ19: TELEPLASTIC | CR19: BOPP OCTH MATE
A20: 01-6023 | B20: NF | C20: 46119 | D20: =IFERROR(VLOOKUP($A20,Hoja3!$A$3:$F$6000,2,FALSE),"") -> TMAHSC083C003 | E20: 16567 | F20: =IFERROR(VLOOKUP($A20,Hoja3!$A$3:$F$6000,6,FALSE),"") -> LAMINACION | G20: 1 | H20: =IFERROR(VLOOKUP($A20,Hoja3!$A$3:$F$6000,5,FALSE),"") -> MCL | I20: =IFERROR(VLOOKUP($A20,Hoja3!$A$3:$F$6000,3,FALSE),"") -> ALIMENTOS HEINZ, C.A. | J20: =IFERROR(VLOOKUP($A20,Hoja3!$A$3:$F$6000,4,FALSE),"") -> LAMINACION IMPRESA GELATINA SONRISSA FRAMBUESA 132g. | K20: 1800 | L20: =30+60+25 -> 115 | M20: 0 | N20: 50 | O20: 0 | P20: 0 | Q20: 0 | R20: 0 | S20: 10 | T20: 10 | U20: 0 | V20: 0 | W20: 0 | X20: 0 | Y20: 0 | Z20: 355 | AA20: 25 | AB20: 0 | AC20: 0 | AD20: =SUM(L20:AC20) -> 565 | AE20: 95.4 | AF20: =SUM(AD20:AE20) -> 660.4 | AG20: =AF20/(60*24) -> 0.45861111 | AH20: =IFERROR(AE20/AF20,0) -> 0.1444579 | AI20: 23200 | AJ20: 18 | AK20: 1000 | AL20: =IF(AM20=0,0,(+AI20*AK20/1000)) -> 23200 | AM20: 432.7 | AN20: 6 | AO20: 60 | AP20: 17 | AQ20: 30 | AR20: 16 | AS20: 20 | AT20: 0 | AU20: 13 | AV20: =SUM(AO20:AU20) -> 156 | AW20: =+(AM20+(BR20*50/100))+(BS20*30/100)-BB20 -> 458.8 | AX20: 0 | AY20: 0 | AZ20: 0 | BA20: 0 | BB20: 0 | BC20: 30 | BD20: 14 | BE20: 9 | BF20: 10 | BG20: 17 | BH20: 0 | BI20: 9 | BJ20: =SUM(BC20:BI20) -> 89 | BK20: 21008 | BL20: =IFERROR(+BO20*1000/((BK20)*(BM20/1000)),0) -> 19.040366 | BM20: =AK20 -> 1000 | BN20: =+BK20*BM20/1000 -> 21008 | BO20: =418.6-18.6 -> 400 | BP20: 0 | BQ20: 0 | BR20: =AO20-BC20 -> 30 | BS20: =(AP20+AQ20+AR20+AS20+AT20+AU20)-(BD20+BE20+BF20+BG20+BH20+BI20) -> 37 | BT20: =BR20+BS20 -> 67 | BU20: =IFERROR(+BK20/AE20,0) -> 220.20964 | BV20: =IFERROR(+BK20/(AF20),0) -> 31.811024 | BW20: =IFERROR(+(AI20-AZ20)-BK20,0) -> 2192 | BX20: =IFERROR(+BW20/BK20,0) -> 0.1043412 | BY20: =IFERROR(+(AL20-BA20)-BN20,0) -> 2192 | BZ20: =IFERROR(+BY20/BN20,0) -> 0.1043412 | CA20: =IFERROR(+AW20-(BO20),0) -> 58.8 | CB20: =IFERROR(+CA20/BO20,1) -> 0.147 | CC20: 0 | CD20: 0 | CE20: Aprobacion se realiza estandar de color, franjas verticales en color magenta, se sacan varias muestras ajustando color cyan magenta y negro | CF20: =IFERROR((BT20*1000)/BN20,"") -> 3.1892612 | CG20: APROBACION | CH20: 1 | CI20: 3500 | CJ20: =IF(BW20=0,"",CI20-BW20) -> 1308 | CK20: {=_xlfn.IFS(CJ20>0,"CUMPLE",CJ20<0,"NO CUMPLE",CJ20="","")} -> CUMPLE | CL20: 46108 | CM20: {=_xlfn.IFS(CL20-C20 > 0,"CUMPLE",CL20-A20 < 0,"NO CUMPLE")} -> NO CUMPLE | CN20: 21500 | CO20: =BK20-CN20 -> -492 | CP20: 1200 | CQ20: OPPFILM | CR20: BOPP SC TRANSPARENTE
A21: 01-6017 | B21: NF | C21: 46120 | D21: =IFERROR(VLOOKUP($A21,Hoja3!$A$3:$F$6000,2,FALSE),"") -> TMAHSK086A002 | E21: 16565 | F21: =IFERROR(VLOOKUP($A21,Hoja3!$A$3:$F$6000,6,FALSE),"") -> LAMINACION | G21: 1 | H21: =IFERROR(VLOOKUP($A21,Hoja3!$A$3:$F$6000,5,FALSE),"") -> MCL | I21: =IFERROR(VLOOKUP($A21,Hoja3!$A$3:$F$6000,3,FALSE),"") -> ALIMENTOS HEINZ, C.A. | J21: =IFERROR(VLOOKUP($A21,Hoja3!$A$3:$F$6000,4,FALSE),"") -> LAMINACION IMPRESA SACHET KETCHUP 10g (frente) | K21: 4600 | L21: 27.5 | M21: 0 | N21: =76+5 -> 81 | O21: 0 | P21: 50 | Q21: 0 | R21: 0 | S21: 62 | T21: 10 | U21: 0 | V21: 0 | W21: 0 | X21: 10 | Y21: 0 | Z21: 70 | AA21: 20 | AB21: 0 | AC21: 0 | AD21: =SUM(L21:AC21) -> 330.5 | AE21: 267 | AF21: =SUM(AD21:AE21) -> 597.5 | AG21: =AF21/(60*24) -> 0.41493056 | AH21: =IFERROR(AE21/AF21,0) -> 0.44686192 | AI21: =111575/2 -> 55787.5 | AJ21: 17 | AK21: 990 | AL21: =IF(AM21=0,0,(+AI21*AK21/1000)) -> 55229.625 | AM21: =1853/2 -> 926.5 | AN21: 6 | AO21: 430 | AP21: 0 | AQ21: 38 | AR21: 22 | AS21: 23 | AT21: 140 | AU21: 24 | AV21: =SUM(AO21:AU21) -> 677 | AW21: =+(AM21+(BR21*50/100))+(BS21*30/100)-BB21 -> 1047.5 | AX21: 0 | AY21: 0 | AZ21: 0 | BA21: 0 | BB21: 0 | BC21: 254 | BD21: 0 | BE21: 21 | BF21: 14 | BG21: 14 | BH21: 72 | BI21: 16 | BJ21: =SUM(BC21:BI21) -> 391 | BK21: =109930/2 -> 54965 | BL21: =IFERROR(+BO21*1000/((BK21)*(BM21/1000)),0) -> 18.643636 | BM21: =AK21 -> 990 | BN21: =+BK21*BM21/1000 -> 54415.35 | BO21: =2029/2 -> 1014.5 | BP21: 0 | BQ21: 0 | BR21: =AO21-BC21 -> 176 | BS21: =(AP21+AQ21+AR21+AS21+AT21+AU21)-(BD21+BE21+BF21+BG21+BH21+BI21) -> 110 | BT21: =BR21+BS21 -> 286 | BU21: =IFERROR(+BK21/AE21,0) -> 205.86142 | BV21: =IFERROR(+BK21/(AF21),0) -> 91.991632 | BW21: =IFERROR(+(AI21-AZ21)-BK21,0) -> 822.5 | BX21: =IFERROR(+BW21/BK21,0) -> 0.014964068 | BY21: =IFERROR(+(AL21-BA21)-BN21,0) -> 814.275 | BZ21: =IFERROR(+BY21/BN21,0) -> 0.014964068 | CA21: =IFERROR(+AW21-(BO21),0) -> 33 | CB21: =IFERROR(+CA21/BO21,1) -> 0.032528339 | CC21: 0 | CD21: 0 | CE21: Aprobacion, efecto telaraña color cyan, sucio en cyan y negro, se realiza estandar de colores | CF21: =IFERROR((BT21*1000)/BN21,"") -> 5.2558699 | CG21: APROBACION | CH21: 1 | CI21: 3500 | CJ21: =IF(BW21=0,"",CI21-BW21) -> 2677.5 | CK21: {=_xlfn.IFS(CJ21>0,"CUMPLE",CJ21<0,"NO CUMPLE",CJ21="","")} -> CUMPLE | CL21: 46094 | CM21: {=_xlfn.IFS(CL21-C21 > 0,"CUMPLE",CL21-A21 < 0,"NO CUMPLE")} -> NO CUMPLE | CN21: 55000 | CO21: =BK21-CN21 -> -35 | CP21: 950 | CQ21: FLEXAM | CR21: FLEX PET TRANSPARENTE
